Workbook

Sheet non_redundnat
A1: N | B1: L | C1: inc | D1: t | E1: avg_time | F1: MLFMA_time | G1: nearFieldTime | H1: farFieldTime | I1: transferTime | J1: computationTime | K1: share NearField | L1: share FarField
A2: 16384 | B2: 4 | C2: 1 | D2: 16 | E2: 1.3356 | F2: 0.001075 | G2: 0.00021 | H2: 0.000784 | I2: 0 | J2: 0.000169 | K2: =ROUND(G2/F2,2) -> 0.2 | L2: =ROUND(H2/F2,2) -> 0.73
A3: 16384 | B3: 4 | C3: 0 | D3: 64 | E3: 1.30698 | F3: 0.001036 | G3: 0.00058 | H3: 0.000369 | I3: 0 | J3: 0.000538 | K3: =ROUND(G3/F3,2) -> 0.56 | L3: =ROUND(H3/F3,2) -> 0.36
A4: 65536 | B4: 5 | C4: 1 | D4: 16 | E4: 4.27714 | F4: 0.003749 | G4: 0.000668 | H4: 0.002946 | I4: 0 | J4: 0.00061 | K4: =ROUND(G4/F4,2) -> 0.18 | L4: =ROUND(H4/F4,2) -> 0.79
A5: 65536 | B5: 5 | C5: 0 | D5: 64 | E5: 4.6695 | F5: 0.004117 | G5: 0.002478 | H5: 0.001484 | I5: 0 | J5: 0.002401 | K5: =ROUND(G5/F5,2) -> 0.6 | L5: =ROUND(H5/F5,2) -> 0.36
A6: 65536 | B6: 5 | C6: -1 | D6: 256 | E6: 12.22712 | F6: 0.011505 | G6: 0.009944 | H6: 0.001389 | I6: 0 | J6: 0.009867 | K6: =ROUND(G6/F6,2) -> 0.86 | L6: =ROUND(H6/F6,2) -> 0.12
A7: 262144 | B7: 6 | C7: 1 | D7: 16 | E7: 14.89482 | F7: 0.013905 | G7: 0.00221 | H7: 0.011536 | I7: 0 | J7: 0.002136 | K7: =ROUND(G7/F7,2) -> 0.16 | L7: =ROUND(H7/F7,2) -> 0.83
A8: 262144 | B8: 6 | C8: 0 | D8: 64 | E8: 17.07092 | F8: 0.016061 | G8: 0.009443 | H8: 0.00646 | I8: 0 | J8: 0.009364 | K8: =ROUND(G8/F8,2) -> 0.59 | L8: =ROUND(H8/F8,2) -> 0.4
A9: 262144 | B9: 6 | C9: -1 | D9: 256 | E9: 40.15598 | F9: 0.039104 | G9: 0.034378 | H9: 0.004552 | I9: 0 | J9: 0.034289 | K9: =ROUND(G9/F9,2) -> 0.88 | L9: =ROUND(H9/F9,2) -> 0.12
A10: 1048576 | B10: 7 | C10: 1 | D10: 16 | E10: 58.0409 | F10: 0.055515 | G10: 0.008548 | H10: 0.0468 | I10: 0 | J10: 0.008473 | K10: =ROUND(G10/F10,2) -> 0.15 | L10: =ROUND(H10/F10,2) -> 0.84
A11: 1048576 | B11: 7 | C11: 0 | D11: 64 | E11: 58.64498 | F11: 0.05609 | G11: 0.033031 | H11: 0.022897 | I11: 0 | J11: 0.032953 | K11: =ROUND(G11/F11,2) -> 0.59 | L11: =ROUND(H11/F11,2) -> 0.41
A12: 1048576 | B12: 7 | C12: -1 | D12: 256 | E12: 151.9482 | F12: 0.149382 | G12: 0.132116 | H12: 0.017097 | I12: 0 | J12: 0.132026 | K12: =ROUND(G12/F12,2) -> 0.88 | L12: =ROUND(H12/F12,2) -> 0.11
A13: 4194304 | B13: 8 | C13: 1 | D13: 16 | E13: 227.68804 | F13: 0.218648 | G13: 0.033181 | H13: 0.185277 | I13: 0 | J13: 0.033107 | K13: =ROUND(G13/F13,2) -> 0.15 | L13: =ROUND(H13/F13,2) -> 0.85
... A18: 16777216 | B18: 9 | C18: -1 | D18: 256 | E18: 2444.6527 | F18: 2.409607 | G18: 2.134629 | H18: 0.274772 | I18: 0 | J18: 2.134534 | K18: =ROUND(G18/F18,2) -> 0.89 | L18: =ROUND(H18/F18,2) -> 0.11
A21: modeling share NF
A24: Sort based on t
A25: N | B25: L | C25: inc | D25: t | E25: avg_time | F25: MLFMA_time | G25: nearFieldTime | H25: farFieldTime | I25: other time | J25: computationTime | K25: share NearField | L25: share FarField | M25: aLog(t,4)+b
A26: 16384 | B26: 4 | C26: 1 | D26: 16 | E26: 1.3356 | F26: 0.001075 | G26: 0.00021 | H26: 0.000784 | I26: =F26-(G26+H26) -> 8.1e-05 | J26: 0.000169 | K26: =ROUND(G26/F26,2) -> 0.2 | L26: =ROUND(H26/F26,2) -> 0.73 | M26: =0.35*LOG(D26,4)-0.5 -> 0.2
A27: 65536 | B27: 5 | C27: 1 | D27: 16 | E27: 4.27714 | F27: 0.003749 | G27: 0.000668 | H27: 0.002946 | I27: =F27-(G27+H27) -> 0.000135 | J27: 0.00061 | K27: =ROUND(G27/F27,2) -> 0.18 | L27: =ROUND(H27/F27,2) -> 0.79 | M27: =0.35*LOG(D27,4)-0.5 -> 0.2
A28: 262144 | B28: 6 | C28: 1 | D28: 16 | E28: 14.89482 | F28: 0.013905 | G28: 0.00221 | H28: 0.011536 | I28: =F28-(G28+H28) -> 0.000159 | J28: 0.002136 | K28: =ROUND(G28/F28,2) -> 0.16 | L28: =ROUND(H28/F28,2) -> 0.83 | M28: =0.35*LOG(D28,4)-0.5 -> 0.2
A29: 1048576 | B29: 7 | C29: 1 | D29: 16 | E29: 58.0409 | F29: 0.055515 | G29: 0.008548 | H29: 0.0468 | I29: =F29-(G29+H29) -> 0.000167 | J29: 0.008473 | K29: =ROUND(G29/F29,2) -> 0.15 | L29: =ROUND(H29/F29,2) -> 0.84 | M29: =0.35*LOG(D29,4)-0.5 -> 0.2
A30: 4194304 | B30: 8 | C30: 1 | D30: 16 | E30: 227.68804 | F30: 0.218648 | G30: 0.033181 | H30: 0.185277 | I30: =F30-(G30+H30) -> 0.00019 | J30: 0.033107 | K30: =ROUND(G30/F30,2) -> 0.15 | L30: =ROUND(H30/F30,2) -> 0.85 | M30: =0.35*LOG(D30,4)-0.5 -> 0.2
A31: 16777216 | B31: 9 | C31: 1 | D31: 16 | E31: 900.38696 | F31: 0.866678 | G31: 0.131954 | H31: 0.73452 | I31: =F31-(G31+H31) -> 0.000204 | J31: 0.131871 | K31: =ROUND(G31/F31,2) -> 0.15 | L31: =ROUND(H31/F31,2) -> 0.85 | M31: =0.35*LOG(D31,4)-0.5 -> 0.2
A32: 16384 | B32: 4 | C32: 0 | D32: 64 | E32: 1.30698 | F32: 0.001036 | G32: 0.00058 | H32: 0.000369 | I32: =F32-(G32+H32) -> 8.7e-05 | J32: 0.000538 | K32: =ROUND(G32/F32,2) -> 0.56 | L32: =ROUND(H32/F32,2) -> 0.36 | M32: =0.35*LOG(D32,4)-0.5 -> 0.55
A33: 65536 | B33: 5 | C33: 0 | D33: 64 | E33: 4.6695 | F33: 0.004117 | G33: 0.002478 | H33: 0.001484 | I33: =F33-(G33+H33) -> 0.000155 | J33: 0.002401 | K33: =ROUND(G33/F33,2) -> 0.6 | L33: =ROUND(H33/F33,2) -> 0.36 | M33: =0.35*LOG(D33,4)-0.5 -> 0.55
A34: 262144 | B34: 6 | C34: 0 | D34: 64 | E34: 17.07092 | F34: 0.016061 | G34: 0.009443 | H34: 0.00646 | I34: =F34-(G34+H34) -> 0.000158 | J34: 0.009364 | K34: =ROUND(G34/F34,2) -> 0.59 | L34: =ROUND(H34/F34,2) -> 0.4 | M34: =0.35*LOG(D34,4)-0.5 -> 0.55
A35: 1048576 | B35: 7 | C35: 0 | D35: 64 | E35: 58.64498 | F35: 0.05609 | G35: 0.033031 | H35: 0.022897 | I35: =F35-(G35+H35) -> 0.000162 | J35: 0.032953 | K35: =ROUND(G35/F35,2) -> 0.59 | L35: =ROUND(H35/F35,2) -> 0.41 | M35: =0.35*LOG(D35,4)-0.5 -> 0.55
A36: 4194304 | B36: 8 | C36: 0 | D36: 64 | E36: 234.68846 | F36: 0.225745 | G36: 0.131819 | H36: 0.093742 | I36: =F36-(G36+H36) -> 0.000184 | J36: 0.131733 | K36: =ROUND(G36/F36,2) -> 0.58 | L36: =ROUND(H36/F36,2) -> 0.42 | M36: =0.35*LOG(D36,4)-0.5 -> 0.55
A37: 16777216 | B37: 9 | C37: 0 | D37: 64 | E37: 927.75198 | F37: 0.893436 | G37: 0.526557 | H37: 0.366677 | I37: =F37-(G37+H37) -> 0.000202 | J37: 0.526464 | K37: =ROUND(G37/F37,2) -> 0.59 | L37: =ROUND(H37/F37,2) -> 0.41 | M37: =0.35*LOG(D37,4)-0.5 -> 0.55
... A42: 16777216 | B42: 9 | C42: -1 | D42: 256 | E42: 2444.6527 | F42: 2.409607 | G42: 2.134629 | H42: 0.274772 | I42: =F42-(G42+H42) -> 0.000206 | J42: 2.134534 | K42: =ROUND(G42/F42,2) -> 0.89 | L42: =ROUND(H42/F42,2) -> 0.11 | M42: =0.35*LOG(D42,4)-0.5 -> 0.9
A56: modeling untime based on level
F77: log(time) = aLog(N)-bLog(t)-c
A78: N | B78: t | C78: nearFieldTime | D78: farFieldTime | E78: Log FF | F78: aLog(N)-bLog(t)+c | G78: Log NF | H78: aLog(N)-bLog(t)+c | I78: share NF | J78: pred share
A79: 16384 | B79: 16 | C79: 0.00021 | D79: 0.000784 | E79: =LOG(D79) -> -3.1056839 | F79: =0.75*LOG(A79)-0.25*LOG(B79)-5.5 -> -2.640215 | G79: {=LOG(C79:C95)} -> -3.6777807 | H79: =0.75*LOG(A79)+0.25*LOG(B79)-6.5 -> -3.038155 | I79: =C79/(C79+D79) -> 0.21126761 | J79: =POWER(10,H79)/(POWER(10,H79)+POWER(10,F79)) -> 0.28571429
A80: 65536 | B80: 16 | C80: 0.000668 | D80: 0.002946 | E80: =LOG(D80) -> -2.5307673 | F80: =0.75*LOG(A80)-0.25*LOG(B80)-5.5 -> -2.18867 | G80: -3.1752235 | H80: =0.75*LOG(A80)+0.25*LOG(B80)-6.5 -> -2.5866101 | I80: =C80/(C80+D80) -> 0.18483675 | J80: =POWER(10,H80)/(POWER(10,H80)+POWER(10,F80)) -> 0.28571429
A81: 262144 | B81: 16 | C81: 0.00221 | D81: 0.011536 | E81: =LOG(D81) -> -1.9379448 | F81: =0.75*LOG(A81)-0.25*LOG(B81)-5.5 -> -1.7371251 | G81: -2.6556077 | H81: =0.75*LOG(A81)+0.25*LOG(B81)-6.5 -> -2.1350651 | I81: =C81/(C81+D81) -> 0.16077404 | J81: =POWER(10,H81)/(POWER(10,H81)+POWER(10,F81)) -> 0.28571429
A82: 1048576 | B82: 16 | C82: 0.008548 | D82: 0.0468 | E82: =LOG(D82) -> -1.3297541 | F82: =0.75*LOG(A82)-0.25*LOG(B82)-5.5 -> -1.2855801 | G82: -2.0681355 | H82: =0.75*LOG(A82)+0.25*LOG(B82)-6.5 -> -1.6835201 | I82: =C82/(C82+D82) -> 0.15444099 | J82: =POWER(10,H82)/(POWER(10,H82)+POWER(10,F82)) -> 0.28571429
A83: 4194304 | B83: 16 | C83: 0.033181 | D83: 0.185277 | E83: =LOG(D83) -> -0.73217849 | F83: =0.75*LOG(A83)-0.25*LOG(B83)-5.5 -> -0.83403507 | G83: -1.4791105 | H83: =0.75*LOG(A83)+0.25*LOG(B83)-6.5 -> -1.2319751 | I83: =C83/(C83+D83) -> 0.15188732 | J83: =POWER(10,H83)/(POWER(10,H83)+POWER(10,F83)) -> 0.28571429
A84: 16777216 | B84: 16 | C84: 0.131954 | D84: 0.73452 | E84: =LOG(D84) -> -0.13399637 | F84: =0.75*LOG(A84)-0.25*LOG(B84)-5.5 -> -0.38249007 | G84: -0.87957744 | H84: =0.75*LOG(A84)+0.25*LOG(B84)-6.5 -> -0.78043008 | I84: =C84/(C84+D84) -> 0.15228847 | J84: =POWER(10,H84)/(POWER(10,H84)+POWER(10,F84)) -> 0.28571429
A85: 16384 | B85: 64 | C85: 0.00058 | D85: 0.000369 | E85: =LOG(D85) -> -3.4329736 | F85: =0.75*LOG(A85)-0.25*LOG(B85)-5.5 -> -2.79073 | G85: -3.236572 | H85: =0.75*LOG(A85)+0.25*LOG(B85)-6.5 -> -2.8876401 | I85: =C85/(C85+D85) -> 0.61116965 | J85: =POWER(10,H85)/(POWER(10,H85)+POWER(10,F85)) -> 0.44444444
...

Sheet X level inc
A1: test | E1: time | M1: X
A2: N | B2: L | C2: inc | D2: t | E2: avg_time | F2: MLFMA_time | G2: nearFieldTime | H2: farFieldTime | I2: transferTime | J2: computationTime | K2: share NearField | L2: share FarField | M2: avg_time | N2: MLFMA_time | O2: nearFieldTime | P2: farFieldTime | Q2: computationTime
A3: 16384 | B3: 4 | C3: 1 | D3: 16 | E3: 1.3356 | F3: 0.001075 | G3: 0.00021 | H3: 0.000784 | I3: 0 | J3: 0.000169 | K3: =ROUND(G3/F3,2) -> 0.2 | L3: =ROUND(H3/F3,2) -> 0.73 | M3: =ROUND(E$4/E3,2) -> 0.98 | N3: =ROUND(F$4/F3,2) -> 0.96 | O3: =ROUND(G$4/G3,2) -> 2.76 | P3: =ROUND(H$4/H3,2) -> 0.47 | Q3: =ROUND(J$4/J3,2) -> 3.18
A4: 16384 | B4: 4 | C4: 0 | D4: 64 | E4: 1.30698 | F4: 0.001036 | G4: 0.00058 | H4: 0.000369 | I4: 0 | J4: 0.000538 | K4: =ROUND(G4/F4,2) -> 0.56 | L4: =ROUND(H4/F4,2) -> 0.36
A5: 65536 | B5: 5 | C5: 1 | D5: 16 | E5: 4.27714 | F5: 0.003749 | G5: 0.000668 | H5: 0.002946 | I5: 0 | J5: 0.00061 | K5: =ROUND(G5/F5,2) -> 0.18 | L5: =ROUND(H5/F5,2) -> 0.79 | M5: =ROUND(E$6/E5,2) -> 1.09 | N5: =ROUND(F$6/F5,2) -> 1.1 | O5: =ROUND(G$6/G5,2) -> 3.71 | P5: =ROUND(H$6/H5,2) -> 0.5 | Q5: =ROUND(J$6/J5,2) -> 3.94
A6: 65536 | B6: 5 | C6: 0 | D6: 64 | E6: 4.6695 | F6: 0.004117 | G6: 0.002478 | H6: 0.001484 | I6: 0 | J6: 0.002401 | K6: =ROUND(G6/F6,2) -> 0.6 | L6: =ROUND(H6/F6,2) -> 0.36
A7: 65536 | B7: 5 | C7: -1 | D7: 256 | E7: 12.22712 | F7: 0.011505 | G7: 0.009944 | H7: 0.001389 | I7: 0 | J7: 0.009867 | K7: =ROUND(G7/F7,2) -> 0.86 | L7: =ROUND(H7/F7,2) -> 0.12 | M7: =ROUND(E$6/E7,2) -> 0.38 | N7: =ROUND(F$6/F7,2) -> 0.36 | O7: =ROUND(G$6/G7,2) -> 0.25 | P7: =ROUND(H$6/H7,2) -> 1.07 | Q7: =ROUND(J$6/J7,2) -> 0.24
A8: 262144 | B8: 6 | C8: 1 | D8: 16 | E8: 14.89482 | F8: 0.013905 | G8: 0.00221 | H8: 0.011536 | I8: 0 | J8: 0.002136 | K8: =ROUND(G8/F8,2) -> 0.16 | L8: =ROUND(H8/F8,2) -> 0.83 | M8: =ROUND(E$9/E8,2) -> 1.15 | N8: =ROUND(F$9/F8,2) -> 1.16 | O8: =ROUND(G$9/G8,2) -> 4.27 | P8: =ROUND(H$9/H8,2) -> 0.56 | Q8: =ROUND(J$9/J8,2) -> 4.38
A9: 262144 | B9: 6 | C9: 0 | D9: 64 | E9: 17.07092 | F9: 0.016061 | G9: 0.009443 | H9: 0.00646 | I9: 0 | J9: 0.009364 | K9: =ROUND(G9/F9,2) -> 0.59 | L9: =ROUND(H9/F9,2) -> 0.4
A10: 262144 | B10: 6 | C10: -1 | D10: 256 | E10: 40.15598 | F10: 0.039104 | G10: 0.034378 | H10: 0.004552 | I10: 0 | J10: 0.034289 | K10: =ROUND(G10/F10,2) -> 0.88 | L10: =ROUND(H10/F10,2) -> 0.12 | M10: =ROUND(E$9/E10,2) -> 0.43 | N10: =ROUND(F$9/F10,2) -> 0.41 | O10: =ROUND(G$9/G10,2) -> 0.27 | P10: =ROUND(H$9/H10,2) -> 1.42 | Q10: =ROUND(J$9/J10,2) -> 0.27
A11: 1048576 | B11: 7 | C11: 1 | D11: 16 | E11: 58.0409 | F11: 0.055515 | G11: 0.008548 | H11: 0.0468 | I11: 0 | J11: 0.008473 | K11: =ROUND(G11/F11,2) -> 0.15 | L11: =ROUND(H11/F11,2) -> 0.84 | M11: =ROUND(E$12/E11,2) -> 1.01 | N11: =ROUND(F$12/F11,2) -> 1.01 | O11: =ROUND(G$12/G11,2) -> 3.86 | P11: =ROUND(H$12/H11,2) -> 0.49 | Q11: =ROUND(J$12/J11,2) -> 3.89
A12: 1048576 | B12: 7 | C12: 0 | D12: 64 | E12: 58.64498 | F12: 0.05609 | G12: 0.033031 | H12: 0.022897 | I12: 0 | J12: 0.032953 | K12: =ROUND(G12/F12,2) -> 0.59 | L12: =ROUND(H12/F12,2) -> 0.41
A13: 1048576 | B13: 7 | C13: -1 | D13: 256 | E13: 151.9482 | F13: 0.149382 | G13: 0.132116 | H13: 0.017097 | I13: 0 | J13: 0.132026 | K13: =ROUND(G13/F13,2) -> 0.88 | L13: =ROUND(H13/F13,2) -> 0.11 | M13: =ROUND(E$12/E13,2) -> 0.39 | N13: =ROUND(F$12/F13,2) -> 0.38 | O13: =ROUND(G$12/G13,2) -> 0.25 | P13: =ROUND(H$12/H13,2) -> 1.34 | Q13: =ROUND(J$12/J13,2) -> 0.25
A14: 4194304 | B14: 8 | C14: 1 | D14: 16 | E14: 227.68804 | F14: 0.218648 | G14: 0.033181 | H14: 0.185277 | I14: 0 | J14: 0.033107 | K14: =ROUND(G14/F14,2) -> 0.15 | L14: =ROUND(H14/F14,2) -> 0.85 | M14: =ROUND(E$15/E14,2) -> 1.03 | N14: =ROUND(F$15/F14,2) -> 1.03 | O14: =ROUND(G$15/G14,2) -> 3.97 | P14: =ROUND(H$15/H14,2) -> 0.51 | Q14: =ROUND(J$15/J14,2) -> 3.98
A15: 4194304 | B15: 8 | C15: 0 | D15: 64 | E15: 234.68846 | F15: 0.225745 | G15: 0.131819 | H15: 0.093742 | I15: 0 | J15: 0.131733 | K15: =ROUND(G15/F15,2) -> 0.58 | L15: =ROUND(H15/F15,2) -> 0.42
A16: 4194304 | B16: 8 | C16: -1 | D16: 256 | E16: 610.77486 | F16: 0.601605 | G16: 0.531288 | H16: 0.070127 | I16: 0 | J16: 0.531195 | K16: =ROUND(G16/F16,2) -> 0.88 | L16: =ROUND(H16/F16,2) -> 0.12 | M16: =ROUND(E$15/E16,2) -> 0.38 | N16: =ROUND(F$15/F16,2) -> 0.38 | O16: =ROUND(G$15/G16,2) -> 0.25 | P16: =ROUND(H$15/H16,2) -> 1.34 | Q16: =ROUND(J$15/J16,2) -> 0.25
A17: 16777216 | B17: 9 | C17: 1 | D17: 16 | E17: 900.38696 | F17: 0.866678 | G17: 0.131954 | H17: 0.73452 | I17: 0 | J17: 0.131871 | K17: =ROUND(G17/F17,2) -> 0.15 | L17: =ROUND(H17/F17,2) -> 0.85 | M17: =ROUND(E$18/E17,2) -> 1.03 | N17: =ROUND(F$18/F17,2) -> 1.03 | O17: =ROUND(G$18/G17,2) -> 3.99 | P17: =ROUND(H$18/H17,2) -> 0.5 | Q17: =ROUND(J$18/J17,2) -> 3.99
A18: 16777216 | B18: 9 | C18: 0 | D18: 64 | E18: 927.75198 | F18: 0.893436 | G18: 0.526557 | H18: 0.366677 | I18: 0 | J18: 0.526464 | K18: =ROUND(G18/F18,2) -> 0.59 | L18: =ROUND(H18/F18,2) -> 0.41
A19: 16777216 | B19: 9 | C19: -1 | D19: 256 | E19: 2444.6527 | F19: 2.409607 | G19: 2.134629 | H19: 0.274772 | I19: 0 | J19: 2.134534 | K19: =ROUND(G19/F19,2) -> 0.89 | L19: =ROUND(H19/F19,2) -> 0.11 | M19: =ROUND(E$18/E19,2) -> 0.38 | N19: =ROUND(F$18/F19,2) -> 0.37 | O19: =ROUND(G$18/G19,2) -> 0.25 | P19: =ROUND(H$18/H19,2) -> 1.33 | Q19: =ROUND(J$18/J19,2) -> 0.25

Sheet redundant RF2
A1: N | B1: L | C1: inc | D1: t | E1: avg_time | F1: MLFMA_time | G1: nearFieldTime | H1: farFieldTime | I1: transferTime | J1: computationTime | K1: share NearField | L1: share FarField | M1: share transfer | N1: share computation
A2: 16384 | B2: 4 | C2: 1 | D2: 16 | E2: 1.3195 | F2: 0.001253 | G2: 0.00038 | H2: 0.000789 | I2: 0.000164 | J2: 0.000174 | K2: =ROUND(G2/F2,2) -> 0.3 | L2: =ROUND(H2/F2,2) -> 0.63 | M2: =ROUND(I2/G2,2) -> 0.43 | N2: =ROUND(J2/G2,2) -> 0.46
A3: 16384 | B3: 4 | C3: 0 | D3: 64 | E3: 1.32048 | F3: 0.001692 | G3: 0.001239 | H3: 0.000367 | I3: 0.000594 | J3: 0.000603 | K3: =ROUND(G3/F3,2) -> 0.73 | L3: =ROUND(H3/F3,2) -> 0.22 | M3: =ROUND(I3/G3,2) -> 0.48 | N3: =ROUND(J3/G3,2) -> 0.49
A4: 65536 | B4: 5 | C4: 1 | D4: 16 | E4: 4.18462 | F4: 0.003878 | G4: 0.000775 | H4: 0.002956 | I4: 0.000135 | J4: 0.000565 | K4: =ROUND(G4/F4,2) -> 0.2 | L4: =ROUND(H4/F4,2) -> 0.76 | M4: =ROUND(I4/G4,2) -> 0.17 | N4: =ROUND(J4/G4,2) -> 0.73
A5: 65536 | B5: 5 | C5: 0 | D5: 64 | E5: 4.223 | F5: 0.004397 | G5: 0.00276 | H5: 0.001485 | I5: 0.000614 | J5: 0.002067 | K5: =ROUND(G5/F5,2) -> 0.63 | L5: =ROUND(H5/F5,2) -> 0.34 | M5: =ROUND(I5/G5,2) -> 0.22 | N5: =ROUND(J5/G5,2) -> 0.75
A6: 65536 | B6: 5 | C6: -1 | D6: 256 | E6: 10.73642 | F6: 0.01804 | G6: 0.016394 | H6: 0.001446 | I6: 0.007864 | J6: 0.008428 | K6: =ROUND(G6/F6,2) -> 0.91 | L6: =ROUND(H6/F6,2) -> 0.08 | M6: =ROUND(I6/G6,2) -> 0.48 | N6: =ROUND(J6/G6,2) -> 0.51
A7: 262144 | B7: 6 | C7: 1 | D7: 16 | E7: 14.45982 | F7: 0.013878 | G7: 0.002181 | H7: 0.011542 | I7: 0.000134 | J7: 0.001972 | K7: =ROUND(G7/F7,2) -> 0.16 | L7: =ROUND(H7/F7,2) -> 0.83 | M7: =ROUND(I7/G7,2) -> 0.06 | N7: =ROUND(J7/G7,2) -> 0.9
A8: 262144 | B8: 6 | C8: 0 | D8: 64 | E8: 14.19186 | F8: 0.014047 | G8: 0.008086 | H8: 0.005803 | I8: 0.000579 | J8: 0.007428 | K8: =ROUND(G8/F8,2) -> 0.58 | L8: =ROUND(H8/F8,2) -> 0.41 | M8: =ROUND(I8/G8,2) -> 0.07 | N8: =ROUND(J8/G8,2) -> 0.92
A9: 262144 | B9: 6 | C9: -1 | D9: 256 | E9: 34.60752 | F9: 0.041726 | G9: 0.037054 | H9: 0.004505 | I9: 0.007885 | J9: 0.029089 | K9: =ROUND(G9/F9,2) -> 0.89 | L9: =ROUND(H9/F9,2) -> 0.11 | M9: =ROUND(I9/G9,2) -> 0.21 | N9: =ROUND(J9/G9,2) -> 0.79
A10: 1048576 | B10: 7 | C10: 1 | D10: 16 | E10: 57.93654 | F10: 0.056763 | G10: 0.008483 | H10: 0.048113 | I10: 0.000573 | J10: 0.007828 | K10: =ROUND(G10/F10,2) -> 0.15 | L10: =ROUND(H10/F10,2) -> 0.85 | M10: =ROUND(I10/G10,2) -> 0.07 | N10: =ROUND(J10/G10,2) -> 0.92
A11: 1048576 | B11: 7 | C11: 0 | D11: 64 | E11: 58.11314 | F11: 0.061093 | G11: 0.036419 | H11: 0.024509 | I11: 0.004813 | J11: 0.031528 | K11: =ROUND(G11/F11,2) -> 0.6 | L11: =ROUND(H11/F11,2) -> 0.4 | M11: =ROUND(I11/G11,2) -> 0.13 | N11: =ROUND(J11/G11,2) -> 0.87
A12: 1048576 | B12: 7 | C12: -1 | D12: 256 | E12: 136.08998 | F12: 0.142142 | G12: 0.124783 | H12: 0.017191 | I12: 0.007853 | J12: 0.116844 | K12: =ROUND(G12/F12,2) -> 0.88 | L12: =ROUND(H12/F12,2) -> 0.12 | M12: =ROUND(I12/G12,2) -> 0.06 | N12: =ROUND(J12/G12,2) -> 0.94
A13: 4194304 | B13: 8 | C13: 1 | D13: 16 | E13: 222.032 | F13: 0.216286 | G13: 0.030673 | H13: 0.185423 | I13: 0.00041 | J13: 0.030186 | K13: =ROUND(G13/F13,2) -> 0.14 | L13: =ROUND(H13/F13,2) -> 0.86 | M13: =ROUND(I13/G13,2) -> 0.01 | N13: =ROUND(J13/G13,2) -> 0.98
... A18: 16777216 | B18: 9 | C18: -1 | D18: 256 | E18: 2209.0029 | F18: 2.266303 | G18: 1.991192 | H18: 0.274896 | I18: 0.07977 | J18: 1.911331 | K18: =ROUND(G18/F18,2) -> 0.88 | L18: =ROUND(H18/F18,2) -> 0.12 | M18: =ROUND(I18/G18,2) -> 0.04 | N18: =ROUND(J18/G18,2) -> 0.96
A32: modeling Shaer NF
A35: N | B35: L | C35: inc | D35: t | E35: share NearField | F35: share FarField | G35: a/N+bLog(t)+c | H35: Model 1
A36: 16384 | B36: 4 | C36: 1 | D36: 16 | E36: 0.3 | F36: 0.63 | G36: =(LOG(D36,4)+5000/A36-1.5)/EXP(1) -> 0.29620762 | H36: =0.37*LOG(D36,4)+1839.4/A36-0.55 -> 0.30226807
A37: 65536 | B37: 5 | C37: 1 | D37: 16 | E37: 0.2 | F37: 0.76 | G37: =(LOG(D37,4)+5000/A37-1.5)/EXP(1) -> 0.21200669 | H37: =0.37*LOG(D37,4)+1839.4/A37-0.55 -> 0.21806702
A38: 262144 | B38: 6 | C38: 1 | D38: 16 | E38: 0.16 | F38: 0.83 | G38: =(LOG(D38,4)+5000/A38-1.5)/EXP(1) -> 0.19095646 | H38: =0.37*LOG(D38,4)+1839.4/A38-0.55 -> 0.19701675
A39: 1048576 | B39: 7 | C39: 1 | D39: 16 | E39: 0.15 | F39: 0.85 | G39: =(LOG(D39,4)+5000/A39-1.5)/EXP(1) -> 0.18569391 | H39: =0.37*LOG(D39,4)+1839.4/A39-0.55 -> 0.19175419
A40: 4194304 | B40: 8 | C40: 1 | D40: 16 | E40: 0.14 | F40: 0.86 | G40: =(LOG(D40,4)+5000/A40-1.5)/EXP(1) -> 0.18437827 | H40: =0.37*LOG(D40,4)+1839.4/A40-0.55 -> 0.19043855
A41: 16777216 | B41: 9 | C41: 1 | D41: 16 | E41: 0.14 | F41: 0.86 | G41: =(LOG(D41,4)+5000/A41-1.5)/EXP(1) -> 0.18404936 | H41: =0.37*LOG(D41,4)+1839.4/A41-0.55 -> 0.19010964
A42: 16384 | B42: 4 | C42: 0 | D42: 64 | E42: 0.73 | F42: 0.22 | G42: =(LOG(D42,4)+5000/A42-1.5)/EXP(1) -> 0.66408706 | H42: =0.37*LOG(D42,4)+1839.4/A42-0.55 -> 0.67226807
A43: 65536 | B43: 5 | C43: 0 | D43: 64 | E43: 0.63 | F43: 0.34 | G43: =(LOG(D43,4)+5000/A43-1.5)/EXP(1) -> 0.57988614 | H43: =0.37*LOG(D43,4)+1839.4/A43-0.55 -> 0.58806702
A44: 262144 | B44: 6 | C44: 0 | D44: 64 | E44: 0.58 | F44: 0.41 | G44: =(LOG(D44,4)+5000/A44-1.5)/EXP(1) -> 0.55883591 | H44: =0.37*LOG(D44,4)+1839.4/A44-0.55 -> 0.56701675
A45: 1048576 | B45: 7 | C45: 0 | D45: 64 | E45: 0.6 | F45: 0.4 | G45: =(LOG(D45,4)+5000/A45-1.5)/EXP(1) -> 0.55357335 | H45: =0.37*LOG(D45,4)+1839.4/A45-0.55 -> 0.56175419
A46: 4194304 | B46: 8 | C46: 0 | D46: 64 | E46: 0.57 | F46: 0.43 | G46: =(LOG(D46,4)+5000/A46-1.5)/EXP(1) -> 0.55225771 | H46: =0.37*LOG(D46,4)+1839.4/A46-0.55 -> 0.56043855
A47: 16777216 | B47: 9 | C47: 0 | D47: 64 | E47: 0.57 | F47: 0.43 | G47: =(LOG(D47,4)+5000/A47-1.5)/EXP(1) -> 0.5519288 | H47: =0.37*LOG(D47,4)+1839.4/A47-0.55 -> 0.56010964
... A52: 16777216 | B52: 9 | C52: -1 | D52: 256 | E52: 0.88 | F52: 0.12 | G52: =(LOG(D52,4)+5000/A52-1.5)/EXP(1) -> 0.91980824 | H52: =0.37*LOG(D52,4)+1839.4/A52-0.55 -> 0.93010964
A56: modeling computation time
A60: N | B60: L | C60: inc | D60: t | E60: transferTime | F60: computationTime | G60: Shaer Transfer | H60: Share Computation | I60: Model 1 | J60: RMSE
A61: 16384 | B61: 4 | C61: 1 | D61: 16 | E61: 0.000164 | F61: 0.000174 | G61: =E61/(E61+F61) -> 0.4852071 | H61: =F61/(E61+F61) -> 0.5147929 | I61: =((A61*D61)-LOG(A61,4))/2200000000 -> 0.00011915318 | J61: =ABS(I61-F61)/F61 -> 0.3152116
A62: 16384 | B62: 4 | C62: 0 | D62: 64 | E62: 0.000594 | F62: 0.000603 | G62: =E62/(E62+F62) -> 0.4962406 | H62: =F62/(E62+F62) -> 0.5037594 | I62: =((A62*D62)-LOG(A62,4))/2200000000 -> 0.00047662227 | J62: =ABS(I62-F62)/F62 -> 0.20958164
A63: 65536 | B63: 5 | C63: 1 | D63: 16 | E63: 0.000135 | F63: 0.000565 | G63: =E63/(E63+F63) -> 0.19285714 | H63: =F63/(E63+F63) -> 0.80714286 | I63: =((A63*D63)-LOG(A63,4))/2200000000 -> 0.00047662182 | J63: =ABS(I63-F63)/F63 -> 0.15642156
A64: 65536 | B64: 5 | C64: 0 | D64: 64 | E64: 0.000614 | F64: 0.002067 | G64: =E64/(E64+F64) -> 0.22901902 | H64: =F64/(E64+F64) -> 0.77098098 | I64: =((A64*D64)-LOG(A64,4))/2200000000 -> 0.0019064982 | J64: =ABS(I64-F64)/F64 -> 0.077649646
A65: 65536 | B65: 5 | C65: -1 | D65: 256 | E65: 0.007844 | F65: 0.008029 | G65: =E65/(E65+F65) -> 0.49417249 | H65: =F65/(E65+F65) -> 0.50582751 | I65: =((A65*D65)-LOG(A65,4))/2200000000 -> 0.0076260036 | J65: =ABS(I65-F65)/F65 -> 0.050192597
A66: 262144 | B66: 6 | C66: 1 | D66: 16 | E66: 0.000134 | F66: 0.001972 | G66: =E66/(E66+F66) -> 0.06362773 | H66: =F66/(E66+F66) -> 0.93637227 | I66: =((A66*D66)-LOG(A66,4))/2200000000 -> 0.0019064977 | J66: =ABS(I66-F66)/F66 -> 0.033216163
A67: 262144 | B67: 6 | C67: 0 | D67: 64 | E67: 0.000579 | F67: 0.007428 | G67: =E67/(E67+F67) -> 0.072311727 | H67: =F67/(E67+F67) -> 0.92768827 | I67: =((A67*D67)-LOG(A67,4))/2200000000 -> 0.0076260032 | J67: =ABS(I67-F67)/F67 -> 0.026656325
A68: 262144 | B68: 6 | C68: -1 | D68: 256 | E68: 0.007885 | F68: 0.029089 | G68: =E68/(E68+F68) -> 0.21325797 | H68: =F68/(E68+F68) -> 0.78674203 | I68: =((A68*D68)-LOG(A68,4))/2200000000 -> 0.030504025 | J68: =ABS(I68-F68)/F68 -> 0.048644677
A69: 1048576 | B69: 7 | C69: 1 | D69: 16 | E69: 0.000573 | F69: 0.007828 | G69: =E69/(E69+F69) -> 0.068206166 | H69: =F69/(E69+F69) -> 0.93179383 | I69: =((A69*D69)-LOG(A69,4))/2200000000 -> 0.0076260027 | J69: =ABS(I69-F69)/F69 -> 0.025804455
...

Sheet X redundant
N1: speedup to base level non-redundant
A2: N | B2: L | C2: inc | D2: t | E2: avg_time | F2: MLFMA_time | G2: nearFieldTime | H2: farFieldTime | I2: computationTime | J2: share NearField | K2: share FarField | L2: ERR X formula | M2: for plot | N2: MLFMA | O2: Computation
A3: ='redundant RF2'!A2 -> 16384 | B3: ='redundant RF2'!B2 -> 4 | C3: ='redundant RF2'!C2 -> 1 | D3: ='redundant RF2'!D2 -> 16 | E3: =ROUND(non_redundnat!E2/'redundant RF2'!E2,2) -> 1.01 | F3: =ROUND(non_redundnat!F2/'redundant RF2'!F2,2) -> 0.86 | G3: =ROUND(non_redundnat!G2/'redundant RF2'!G2,2) -> 0.55 | H3: =ROUND(non_redundnat!H2/'redundant RF2'!H2,2) -> 0.99 | I3: =ROUND(non_redundnat!J2/'redundant RF2'!J2,2) -> 0.97 | J3: ='redundant RF2'!K2 -> 0.3 | K3: ='redundant RF2'!L2 -> 0.63 | L3: =ABS((1/('redundant RF2'!K2/'X redundant'!G3+'redundant RF2'!L2/'X redundant'!H3)) - F3) / F3 -> 0.016100179 | M3: =POWER(G3,5) -> 0.050328438 | N3: =non_redundnat!F3/'redundant RF2'!F2 -> 0.82681564 | O3: =non_redundnat!J$3/'redundant RF2'!J2 -> 3.091954
A4: ='redundant RF2'!A3 -> 16384 | B4: ='redundant RF2'!B3 -> 4 | C4: ='redundant RF2'!C3 -> 0 | D4: ='redundant RF2'!D3 -> 64 | E4: =ROUND(non_redundnat!E3/'redundant RF2'!E3,2) -> 0.99 | F4: =ROUND(non_redundnat!F3/'redundant RF2'!F3,2) -> 0.61 | G4: =ROUND(non_redundnat!G3/'redundant RF2'!G3,2) -> 0.47 | H4: =ROUND(non_redundnat!H3/'redundant RF2'!H3,2) -> 1.01 | I4: =ROUND(non_redundnat!J3/'redundant RF2'!J3,2) -> 0.89 | J4: ='redundant RF2'!K3 -> 0.73 | K4: ='redundant RF2'!L3 -> 0.22 | L4: =ABS((1/('redundant RF2'!K3/'X redundant'!G4+'redundant RF2'!L3/'X redundant'!H4)) - F4) / F4 -> 0.07434671 | M4: =POWER(G4,5) -> 0.022934501 | N4: =non_redundnat!F3/'redundant RF2'!F3 -> 0.61229314 | O4: =non_redundnat!J$3/'redundant RF2'!J3 -> 0.89220564
A5: ='redundant RF2'!A4 -> 65536 | B5: ='redundant RF2'!B4 -> 5 | C5: ='redundant RF2'!C4 -> 1 | D5: ='redundant RF2'!D4 -> 16 | E5: =ROUND(non_redundnat!E4/'redundant RF2'!E4,2) -> 1.02 | F5: =ROUND(non_redundnat!F4/'redundant RF2'!F4,2) -> 0.97 | G5: =ROUND(non_redundnat!G4/'redundant RF2'!G4,2) -> 0.86 | H5: =ROUND(non_redundnat!H4/'redundant RF2'!H4,2) -> 1 | I5: =ROUND(non_redundnat!J4/'redundant RF2'!J4,2) -> 1.08 | J5: ='redundant RF2'!K4 -> 0.2 | K5: ='redundant RF2'!L4 -> 0.76 | L5: =ABS((1/('redundant RF2'!K4/'X redundant'!G5+'redundant RF2'!L4/'X redundant'!H5)) - F5) / F5 -> 0.038657378 | M5: =POWER(G5,5) -> 0.47042702 | N5: =non_redundnat!F$5/'redundant RF2'!F4 -> 1.0616297 | O5: =non_redundnat!J$5/'redundant RF2'!J4 -> 4.2495575
A6: ='redundant RF2'!A5 -> 65536 | B6: ='redundant RF2'!B5 -> 5 | C6: ='redundant RF2'!C5 -> 0 | D6: ='redundant RF2'!D5 -> 64 | E6: =ROUND(non_redundnat!E5/'redundant RF2'!E5,2) -> 1.11 | F6: =ROUND(non_redundnat!F5/'redundant RF2'!F5,2) -> 0.94 | G6: =ROUND(non_redundnat!G5/'redundant RF2'!G5,2) -> 0.9 | H6: =ROUND(non_redundnat!H5/'redundant RF2'!H5,2) -> 1 | I6: =ROUND(non_redundnat!J5/'redundant RF2'!J5,2) -> 1.16 | J6: ='redundant RF2'!K5 -> 0.63 | K6: ='redundant RF2'!L5 -> 0.34 | L6: =ABS((1/('redundant RF2'!K5/'X redundant'!G6+'redundant RF2'!L5/'X redundant'!H6)) - F6) / F6 -> 0.022913257 | M6: =POWER(G6,5) -> 0.59049 | N6: =non_redundnat!F$5/'redundant RF2'!F5 -> 0.93632022 | O6: =non_redundnat!J$5/'redundant RF2'!J5 -> 1.1615868
A7: ='redundant RF2'!A6 -> 65536 | B7: ='redundant RF2'!B6 -> 5 | C7: ='redundant RF2'!C6 -> -1 | D7: ='redundant RF2'!D6 -> 256 | E7: =ROUND(non_redundnat!E6/'redundant RF2'!E6,2) -> 1.14 | F7: =ROUND(non_redundnat!F6/'redundant RF2'!F6,2) -> 0.64 | G7: =ROUND(non_redundnat!G6/'redundant RF2'!G6,2) -> 0.61 | H7: =ROUND(non_redundnat!H6/'redundant RF2'!H6,2) -> 0.96 | I7: =ROUND(non_redundnat!J6/'redundant RF2'!J6,2) -> 1.17 | J7: ='redundant RF2'!K6 -> 0.91 | K7: ='redundant RF2'!L6 -> 0.08 | L7: =ABS((1/('redundant RF2'!K6/'X redundant'!G7+'redundant RF2'!L6/'X redundant'!H7)) - F7) / F7 -> 0.0080225499 | M7: =POWER(G7,5) -> 0.08445963 | N7: =non_redundnat!F$5/'redundant RF2'!F6 -> 0.22821508 | O7: =non_redundnat!J$5/'redundant RF2'!J6 -> 0.28488372
A8: ='redundant RF2'!A7 -> 262144 | B8: ='redundant RF2'!B7 -> 6 | C8: ='redundant RF2'!C7 -> 1 | D8: ='redundant RF2'!D7 -> 16 | E8: =ROUND(non_redundnat!E7/'redundant RF2'!E7,2) -> 1.03 | F8: =ROUND(non_redundnat!F7/'redundant RF2'!F7,2) -> 1 | G8: =ROUND(non_redundnat!G7/'redundant RF2'!G7,2) -> 1.01 | H8: =ROUND(non_redundnat!H7/'redundant RF2'!H7,2) -> 1 | I8: =ROUND(non_redundnat!J7/'redundant RF2'!J7,2) -> 1.08 | J8: ='redundant RF2'!K7 -> 0.16 | K8: ='redundant RF2'!L7 -> 0.83 | L8: =ABS((1/('redundant RF2'!K7/'X redundant'!G8+'redundant RF2'!L7/'X redundant'!H8)) - F8) / F8 -> 0.011719924 | M8: =POWER(G8,5) -> 1.0510101 | N8: =non_redundnat!F$8/'redundant RF2'!F7 -> 1.1572993 | O8: =non_redundnat!J$8/'redundant RF2'!J7 -> 4.7484787
A9: ='redundant RF2'!A8 -> 262144 | B9: ='redundant RF2'!B8 -> 6 | C9: ='redundant RF2'!C8 -> 0 | D9: ='redundant RF2'!D8 -> 64 | E9: =ROUND(non_redundnat!E8/'redundant RF2'!E8,2) -> 1.2 | F9: =ROUND(non_redundnat!F8/'redundant RF2'!F8,2) -> 1.14 | G9: =ROUND(non_redundnat!G8/'redundant RF2'!G8,2) -> 1.17 | H9: =ROUND(non_redundnat!H8/'redundant RF2'!H8,2) -> 1.11 | I9: =ROUND(non_redundnat!J8/'redundant RF2'!J8,2) -> 1.26 | J9: ='redundant RF2'!K8 -> 0.58 | K9: ='redundant RF2'!L8 -> 0.41 | L9: =ABS((1/('redundant RF2'!K8/'X redundant'!G9+'redundant RF2'!L8/'X redundant'!H9)) - F9) / F9 -> 0.013983557 | M9: =POWER(G9,5) -> 2.192448 | N9: =non_redundnat!F$8/'redundant RF2'!F8 -> 1.1433758 | O9: =non_redundnat!J$8/'redundant RF2'!J8 -> 1.2606354
A10: ='redundant RF2'!A9 -> 262144 | B10: ='redundant RF2'!B9 -> 6 | C10: ='redundant RF2'!C9 -> -1 | D10: ='redundant RF2'!D9 -> 256 | E10: =ROUND(non_redundnat!E9/'redundant RF2'!E9,2) -> 1.16 | F10: =ROUND(non_redundnat!F9/'redundant RF2'!F9,2) -> 0.94 | G10: =ROUND(non_redundnat!G9/'redundant RF2'!G9,2) -> 0.93 | H10: =ROUND(non_redundnat!H9/'redundant RF2'!H9,2) -> 1.01 | I10: =ROUND(non_redundnat!J9/'redundant RF2'!J9,2) -> 1.18 | J10: ='redundant RF2'!K9 -> 0.89 | K10: ='redundant RF2'!L9 -> 0.11 | L10: =ABS((1/('redundant RF2'!K9/'X redundant'!G10+'redundant RF2'!L9/'X redundant'!H10)) - F10) / F10 -> 0.00194235 | M10: =POWER(G10,5) -> 0.69568837 | N10: =non_redundnat!F$8/'redundant RF2'!F9 -> 0.38491588 | O10: =non_redundnat!J$8/'redundant RF2'!J9 -> 0.32190863
A11: ='redundant RF2'!A10 -> 1048576 | B11: ='redundant RF2'!B10 -> 7 | C11: ='redundant RF2'!C10 -> 1 | D11: ='redundant RF2'!D10 -> 16 | E11: =ROUND(non_redundnat!E10/'redundant RF2'!E10,2) -> 1 | F11: =ROUND(non_redundnat!F10/'redundant RF2'!F10,2) -> 0.98 | G11: =ROUND(non_redundnat!G10/'redundant RF2'!G10,2) -> 1.01 | H11: =ROUND(non_redundnat!H10/'redundant RF2'!H10,2) -> 0.97 | I11: =ROUND(non_redundnat!J10/'redundant RF2'!J10,2) -> 1.08 | J11: ='redundant RF2'!K10 -> 0.15 | K11: ='redundant RF2'!L10 -> 0.85 | L11: =ABS((1/('redundant RF2'!K10/'X redundant'!G11+'redundant RF2'!L10/'X redundant'!H11)) - F11) / F11 -> 0.0042889666 | M11: =POWER(G11,5) -> 1.0510101 | N11: =non_redundnat!F$11/'redundant RF2'!F10 -> 0.98814369 | O11: =non_redundnat!J$11/'redundant RF2'!J10 -> 4.2096321
A12: ='redundant RF2'!A11 -> 1048576 | B12: ='redundant RF2'!B11 -> 7 | C12: ='redundant RF2'!C11 -> 0 | D12: ='redundant RF2'!D11 -> 64 | E12: =ROUND(non_redundnat!E11/'redundant RF2'!E11,2) -> 1.01 | F12: =ROUND(non_redundnat!F11/'redundant RF2'!F11,2) -> 0.92 | G12: =ROUND(non_redundnat!G11/'redundant RF2'!G11,2) -> 0.91 | H12: =ROUND(non_redundnat!H11/'redundant RF2'!H11,2) -> 0.93 | I12: =ROUND(non_redundnat!J11/'redundant RF2'!J11,2) -> 1.05 | J12: ='redundant RF2'!K11 -> 0.6 | K12: ='redundant RF2'!L11 -> 0.4 | L12: =ABS((1/('redundant RF2'!K11/'X redundant'!G12+'redundant RF2'!L11/'X redundant'!H12)) - F12) / F12 -> 0.0022870886 | M12: =POWER(G12,5) -> 0.62403215 | N12: =non_redundnat!F$11/'redundant RF2'!F11 -> 0.91810846 | O12: =non_redundnat!J$11/'redundant RF2'!J11 -> 1.0451979
A13: ='redundant RF2'!A12 -> 1048576 | B13: ='redundant RF2'!B12 -> 7 | C13: ='redundant RF2'!C12 -> -1 | D13: ='redundant RF2'!D12 -> 256 | E13: =ROUND(non_redundnat!E12/'redundant RF2'!E12,2) -> 1.12 | F13: =ROUND(non_redundnat!F12/'redundant RF2'!F12,2) -> 1.05 | G13: =ROUND(non_redundnat!G12/'redundant RF2'!G12,2) -> 1.06 | H13: =ROUND(non_redundnat!H12/'redundant RF2'!H12,2) -> 0.99 | I13: =ROUND(non_redundnat!J12/'redundant RF2'!J12,2) -> 1.13 | J13: ='redundant RF2'!K12 -> 0.88 | K13: ='redundant RF2'!L12 -> 0.12 | L13: =ABS((1/('redundant RF2'!K12/'X redundant'!G13+'redundant RF2'!L12/'X redundant'!H13)) - F13) / F13 -> 0.0010302198 | M13: =POWER(G13,5) -> 1.3382256 | N13: =non_redundnat!F$11/'redundant RF2'!F12 -> 0.39460539 | O13: =non_redundnat!J$11/'redundant RF2'!J12 -> 0.28202561
A14: ='redundant RF2'!A13 -> 4194304 | B14: ='redundant RF2'!B13 -> 8 | C14: ='redundant RF2'!C13 -> 1 | D14: ='redundant RF2'!D13 -> 16 | E14: =ROUND(non_redundnat!E13/'redundant RF2'!E13,2) -> 1.03 | F14: =ROUND(non_redundnat!F13/'redundant RF2'!F13,2) -> 1.01 | G14: =ROUND(non_redundnat!G13/'redundant RF2'!G13,2) -> 1.08 | H14: =ROUND(non_redundnat!H13/'redundant RF2'!H13,2) -> 1 | I14: =ROUND(non_redundnat!J13/'redundant RF2'!J13,2) -> 1.1 | J14: ='redundant RF2'!K13 -> 0.14 | K14: ='redundant RF2'!L13 -> 0.86 | L14: =ABS((1/('redundant RF2'!K13/'X redundant'!G14+'redundant RF2'!L13/'X redundant'!H14)) - F14) / F14 -> 0.00047429893 | M14: =POWER(G14,5) -> 1.4693281 | N14: =non_redundnat!F$14/'redundant RF2'!F13 -> 1.0437338 | O14: =non_redundnat!J$14/'redundant RF2'!J13 -> 4.3640429
A15: ='redundant RF2'!A14 -> 4194304 | B15: ='redundant RF2'!B14 -> 8 | C15: ='redundant RF2'!C14 -> 0 | D15: ='redundant RF2'!D14 -> 64 | E15: =ROUND(non_redundnat!E14/'redundant RF2'!E14,2) -> 1.08 | F15: =ROUND(non_redundnat!F14/'redundant RF2'!F14,2) -> 1.04 | G15: =ROUND(non_redundnat!G14/'redundant RF2'!G14,2) -> 1.06 | H15: =ROUND(non_redundnat!H14/'redundant RF2'!H14,2) -> 1.01 | I15: =ROUND(non_redundnat!J14/'redundant RF2'!J14,2) -> 1.1 | J15: ='redundant RF2'!K14 -> 0.57 | K15: ='redundant RF2'!L14 -> 0.43 | L15: =ABS((1/('redundant RF2'!K14/'X redundant'!G15+'redundant RF2'!L14/'X redundant'!H15)) - F15) / F15 -> 0.0020134979 | M15: =POWER(G15,5) -> 1.3382256 | N15: =non_redundnat!F$14/'redundant RF2'!F14 -> 1.0406304 | O15: =non_redundnat!J$14/'redundant RF2'!J14 -> 1.1044662
A16: ='redundant RF2'!A15 -> 4194304 | B16: ='redundant RF2'!B15 -> 8 | C16: ='redundant RF2'!C15 -> -1 | D16: ='redundant RF2'!D15 -> 256 | E16: =ROUND(non_redundnat!E15/'redundant RF2'!E15,2) -> 1.12 | F16: =ROUND(non_redundnat!F15/'redundant RF2'!F15,2) -> 1.1 | G16: =ROUND(non_redundnat!G15/'redundant RF2'!G15,2) -> 1.11 | H16: =ROUND(non_redundnat!H15/'redundant RF2'!H15,2) -> 1.04 | I16: =ROUND(non_redundnat!J15/'redundant RF2'!J15,2) -> 1.13 | J16: ='redundant RF2'!K15 -> 0.88 | K16: ='redundant RF2'!L15 -> 0.12 | L16: =ABS((1/('redundant RF2'!K15/'X redundant'!G16+'redundant RF2'!L15/'X redundant'!H16)) - F16) / F16 -> 0.0010058617 | M16: =POWER(G16,5) -> 1.6850582 | N16: =non_redundnat!F$14/'redundant RF2'!F15 -> 0.41342588 | O16: =non_redundnat!J$14/'redundant RF2'!J15 -> 0.28015244
A17: ='redundant RF2'!A16 -> 16777216 | B17: ='redundant RF2'!B16 -> 9 | C17: ='redundant RF2'!C16 -> 1 | D17: ='redundant RF2'!D16 -> 16 | E17: =ROUND(non_redundnat!E16/'redundant RF2'!E16,2) -> 1.02 | F17: =ROUND(non_redundnat!F16/'redundant RF2'!F16,2) -> 1.01 | G17: =ROUND(non_redundnat!G16/'redundant RF2'!G16,2) -> 1.09 | H17: =ROUND(non_redundnat!H16/'redundant RF2'!H16,2) -> 1 | I17: =ROUND(non_redundnat!J16/'redundant RF2'!J16,2) -> 1.09 | J17: ='redundant RF2'!K16 -> 0.14 | K17: ='redundant RF2'!L16 -> 0.86 | L17: =ABS((1/('redundant RF2'!K16/'X redundant'!G17+'redundant RF2'!L16/'X redundant'!H17)) - F17) / F17 -> 0.0016780405 | M17: =POWER(G17,5) -> 1.538624 | N17: =non_redundnat!F$17/'redundant RF2'!F16 -> 1.0398464 | O17: =non_redundnat!J$17/'redundant RF2'!J16 -> 4.3601309
A18: ='redundant RF2'!A17 -> 16777216 | B18: ='redundant RF2'!B17 -> 9 | C18: ='redundant RF2'!C17 -> 0 | D18: ='redundant RF2'!D17 -> 64 | E18: =ROUND(non_redundnat!E17/'redundant RF2'!E17,2) -> 1.07 | F18: =ROUND(non_redundnat!F17/'redundant RF2'!F17,2) -> 1.05 | G18: =ROUND(non_redundnat!G17/'redundant RF2'!G17,2) -> 1.09 | H18: =ROUND(non_redundnat!H17/'redundant RF2'!H17,2) -> 0.99 | I18: =ROUND(non_redundnat!J17/'redundant RF2'!J17,2) -> 1.1 | J18: ='redundant RF2'!K17 -> 0.57 | K18: ='redundant RF2'!L17 -> 0.43 | L18: =ABS((1/('redundant RF2'!K17/'X redundant'!G18+'redundant RF2'!L17/'X redundant'!H18)) - F18) / F18 -> 0.005116858 | M18: =POWER(G18,5) -> 1.538624 | N18: =non_redundnat!F$17/'redundant RF2'!F17 -> 1.0480999 | O18: =non_redundnat!J$17/'redundant RF2'!J17 -> 1.1002428
A19: ='redundant RF2'!A18 -> 16777216 | B19: ='redundant RF2'!B18 -> 9 | C19: ='redundant RF2'!C18 -> -1 | D19: ='redundant RF2'!D18 -> 256 | E19: =ROUND(non_redundnat!E18/'redundant RF2'!E18,2) -> 1.11 | F19: =ROUND(non_redundnat!F18/'redundant RF2'!F18,2) -> 1.06 | G19: =ROUND(non_redundnat!G18/'redundant RF2'!G18,2) -> 1.07 | H19: =ROUND(non_redundnat!H18/'redundant RF2'!H18,2) -> 1 | I19: =ROUND(non_redundnat!J18/'redundant RF2'!J18,2) -> 1.12 | J19: ='redundant RF2'!K18 -> 0.88 | K19: ='redundant RF2'!L18 -> 0.12 | L19: =ABS((1/('redundant RF2'!K18/'X redundant'!G19+'redundant RF2'!L18/'X redundant'!H19)) - F19) / F19 -> 0.0010253493 | M19: =POWER(G19,5) -> 1.4025517 | N19: =non_redundnat!F$17/'redundant RF2'!F18 -> 0.39422619 | O19: =non_redundnat!J$17/'redundant RF2'!J18 -> 0.27544366
K21: RMSE % | L21: =AVERAGE(L3:L19)*100 -> 1.2153299 | N21: in less dense tree, MLFMA is faster
N22: redundancy is faster in less dense trees, alittle faster than non-redundant
N23: redundancy is fast in large problems, but the peak point is not clear
A34: N | B34: L | C34: inc | D34: t | E34: box | F34: avg_time | G34: MLFMA_time | H34: nearFieldTime | I34: farFieldTime | J34: computationTime | K34: share NearField | L34: share FarField
A35: 1048576 | B35: 7 | C35: 1 | D35: 16 | E35: 4 | F35: 1 | G35: 0.98 | H35: 1.01 | I35: 0.97 | J35: 1.08 | K35: 0.15 | L35: 0.85
A36: 16384 | B36: 4 | C36: 1 | D36: 16 | E36: 4 | F36: 1.01 | G36: 0.86 | H36: 0.55 | I36: 0.99 | J36: 0.97 | K36: 0.3 | L36: 0.63
A37: 65536 | B37: 5 | C37: 1 | D37: 16 | E37: 4 | F37: 1.02 | G37: 0.97 | H37: 0.86 | I37: 1 | J37: 1.08 | K37: 0.2 | L37: 0.76
A38: 16777216 | B38: 9 | C38: 1 | D38: 16 | E38: 4 | F38: 1.02 | G38: 1.01 | H38: 1.09 | I38: 1 | J38: 1.09 | K38: 0.14 | L38: 0.86
A39: 262144 | B39: 6 | C39: 1 | D39: 16 | E39: 4 | F39: 1.03 | G39: 1 | H39: 1.01 | I39: 1 | J39: 1.08 | K39: 0.16 | L39: 0.83
A40: 4194304 | B40: 8 | C40: 1 | D40: 16 | E40: 4 | F40: 1.03 | G40: 1.01 | H40: 1.08 | I40: 1 | J40: 1.1 | K40: 0.14 | L40: 0.86
A41: 16384 | B41: 4 | C41: 0 | D41: 64 | E41: 8 | F41: 0.99 | G41: 0.61 | H41: 0.47 | I41: 1.01 | J41: 0.89 | K41: 0.73 | L41: 0.22
A42: 1048576 | B42: 7 | C42: 0 | D42: 64 | E42: 8 | F42: 1.01 | G42: 0.92 | H42: 0.91 | I42: 0.93 | J42: 1.05 | K42: 0.6 | L42: 0.4
A43: 16777216 | B43: 9 | C43: 0 | D43: 64 | E43: 8 | F43: 1.07 | G43: 1.05 | H43: 1.09 | I43: 0.99 | J43: 1.1 | K43: 0.57 | L43: 0.43
A44: 4194304 | B44: 8 | C44: 0 | D44: 64 | E44: 8 | F44: 1.08 | G44: 1.04 | H44: 1.06 | I44: 1.01 | J44: 1.1 | K44: 0.57 | L44: 0.43
A45: 65536 | B45: 5 | C45: 0 | D45: 64 | E45: 8 | F45: 1.11 | G45: 0.94 | H45: 0.9 | I45: 1 | J45: 1.16 | K45: 0.63 | L45: 0.34
A46: 262144 | B46: 6 | C46: 0 | D46: 64 | E46: 8 | F46: 1.2 | G46: 1.14 | H46: 1.17 | I46: 1.11 | J46: 1.26 | K46: 0.58 | L46: 0.41
... A51: 262144 | B51: 6 | C51: -1 | D51: 256 | E51: 16 | F51: 1.16 | G51: 0.94 | H51: 0.93 | I51: 1.01 | J51: 1.18 | K51: 0.89 | L51: 0.11
