Workbook

Sheet non_redundnat
A1: N | B1: L | C1: inc | D1: t | E1: avg_time | F1: MLFMA_time | G1: nearFieldTime | H1: farFieldTime | I1: transferTime | J1: computationTime | K1: MLFMA_time | L1: nearFieldTime | M1: farFieldTime | N1: transferTime | O1: computationTime | P1: share NearField | Q1: share FarField | R1: share Transfer | S1: share Computation | U1: N | V1: L’=L+1 | W1: L’=L | X1: L’=L+1
A2: 65536 | B2: 5 | C2: 1 | D2: 16 | E2: 5.3835 | F2: 0.006635 | G2: 0.000865 | H2: 0.003789 | I2: 0.000337 | J2: 0.000787 | K2: =G2+H2+I2 -> 0.004991 | L2: =G2+I2 -> 0.001202 | M2: =H2 -> 0.003789 | N2: =I2 -> 0.000337 | O2: =J2 -> 0.000787 | P2: =ROUND(G2/F2,2) -> 0.13 | Q2: =ROUND(H2/F2,2) -> 0.57 | R2: =ROUND(N2/L2,2) -> 0.28 | S2: =ROUND(O2/L2,2) -> 0.65 | U2: 65536 | V2: =P2 -> 0.13 | W2: =P3 -> 0.47 | X2: =P4 -> 0.75
A3: 65536 | B3: 5 | C3: 0 | D3: 64 | E3: 5.5704 | F3: 0.006638 | G3: 0.003097 | H3: 0.001862 | I3: 0.000283 | J3: 0.00304 | K3: =G3+H3+I3 -> 0.005242 | L3: =G3+I3 -> 0.00338 | M3: =H3 -> 0.001862 | N3: =I3 -> 0.000283 | O3: =J3 -> 0.00304 | P3: =ROUND(G3/F3,2) -> 0.47 | Q3: =ROUND(H3/F3,2) -> 0.28 | R3: =ROUND(N3/L3,2) -> 0.08 | S3: =ROUND(O3/L3,2) -> 0.9 | U3: 262144 | V3: =P5 -> 0.12 | W3: =P6 -> 0.47 | X3: =P7 -> 0.88
A4: 65536 | B4: 5 | C4: -1 | D4: 256 | E4: 13.3284 | F4: 0.014627 | G4: 0.01099 | H4: 0.001542 | I4: 0.000359 | J4: 0.01091 | K4: =G4+H4+I4 -> 0.012891 | L4: =G4+I4 -> 0.011349 | M4: =H4 -> 0.001542 | N4: =I4 -> 0.000359 | O4: =J4 -> 0.01091 | P4: =ROUND(G4/F4,2) -> 0.75 | Q4: =ROUND(H4/F4,2) -> 0.11 | R4: =ROUND(N4/L4,2) -> 0.03 | S4: =ROUND(O4/L4,2) -> 0.96 | U4: 1048576 | V4: =P8 -> 0.13 | W4: =P9 -> 0.49 | X4: =P10 -> 0.82
A5: 262144 | B5: 6 | C5: 1 | D5: 16 | E5: 14.998 | F5: 0.018151 | G5: 0.002218 | H5: 0.01164 | I5: 0.000736 | J5: 0.002143 | K5: =G5+H5+I5 -> 0.014594 | L5: =G5+I5 -> 0.002954 | M5: =H5 -> 0.01164 | N5: =I5 -> 0.000736 | O5: =J5 -> 0.002143 | P5: =ROUND(G5/F5,2) -> 0.12 | Q5: =ROUND(H5/F5,2) -> 0.64 | R5: =ROUND(N5/L5,2) -> 0.25 | S5: =ROUND(O5/L5,2) -> 0.73 | U5: 4194304 | V5: =P11 -> 0.13 | W5: =P12 -> 0.49 | X5: =P13 -> 0.82
A6: 262144 | B6: 6 | C6: 0 | D6: 64 | E6: 16.6467 | F6: 0.019678 | G6: 0.009223 | H6: 0.006266 | I6: 0.000732 | J6: 0.00914 | K6: =G6+H6+I6 -> 0.016221 | L6: =G6+I6 -> 0.009955 | M6: =H6 -> 0.006266 | N6: =I6 -> 0.000732 | O6: =J6 -> 0.00914 | P6: =ROUND(G6/F6,2) -> 0.47 | Q6: =ROUND(H6/F6,2) -> 0.32 | R6: =ROUND(N6/L6,2) -> 0.07 | S6: =ROUND(O6/L6,2) -> 0.92 | U6: 16777216 | V6: =P14 -> 0.12 | W6: =P15 -> 0.49 | X6: =P16 -> 0.82
A7: 262144 | B7: 6 | C7: -1 | D7: 256 | E7: 41.6408 | F7: 0.044726 | G7: 0.03569 | H7: 0.004755 | I7: 0.000752 | J7: 0.035605 | K7: =G7+H7+I7 -> 0.041197 | L7: =G7+I7 -> 0.036442 | M7: =H7 -> 0.004755 | N7: =I7 -> 0.000752 | O7: =J7 -> 0.035605 | P7: =ROUND(L7/K7,2) -> 0.88 | Q7: =ROUND(M7/K7,2) -> 0.12 | R7: =ROUND(N7/L7,2) -> 0.02 | S7: =ROUND(O7/L7,2) -> 0.98
A8: 1048576 | B8: 7 | C8: 1 | D8: 16 | E8: 63.92 | F8: 0.0738 | G8: 0.009375 | H8: 0.051786 | I8: 0.002281 | J8: 0.009297 | K8: =G8+H8+I8 -> 0.063442 | L8: =G8+I8 -> 0.011656 | M8: =H8 -> 0.051786 | N8: =I8 -> 0.002281 | O8: =J8 -> 0.009297 | P8: =ROUND(G8/F8,2) -> 0.13 | Q8: =ROUND(H8/F8,2) -> 0.7 | R8: =ROUND(N8/L8,2) -> 0.2 | S8: =ROUND(O8/L8,2) -> 0.8
A9: 1048576 | B9: 7 | C9: 0 | D9: 64 | E9: 65.2872 | F9: 0.075347 | G9: 0.03675 | H9: 0.02579 | I9: 0.002267 | J9: 0.036667 | K9: =G9+H9+I9 -> 0.064807 | L9: =G9+I9 -> 0.039017 | M9: =H9 -> 0.02579 | N9: =I9 -> 0.002267 | O9: =J9 -> 0.036667 | P9: =ROUND(G9/F9,2) -> 0.49 | Q9: =ROUND(H9/F9,2) -> 0.34 | R9: =ROUND(N9/L9,2) -> 0.06 | S9: =ROUND(O9/L9,2) -> 0.94
A10: 1048576 | B10: 7 | C10: -1 | D10: 256 | E10: 156.8589 | F10: 0.166777 | G10: 0.136305 | H10: 0.01783 | I10: 0.002227 | J10: 0.13621 | K10: =G10+H10+I10 -> 0.156362 | L10: =G10+I10 -> 0.138532 | M10: =H10 -> 0.01783 | N10: =I10 -> 0.002227 | O10: =J10 -> 0.13621 | P10: =ROUND(G10/F10,2) -> 0.82 | Q10: =ROUND(H10/F10,2) -> 0.11 | R10: =ROUND(N10/L10,2) -> 0.02 | S10: =ROUND(O10/L10,2) -> 0.98
A11: 4194304 | B11: 8 | C11: 1 | D11: 16 | E11: 229.7879 | F11: 0.267801 | G11: 0.033513 | H11: 0.187315 | I11: 0.008449 | J11: 0.033426 | K11: =G11+H11+I11 -> 0.229277 | L11: =G11+I11 -> 0.041962 | M11: =H11 -> 0.187315 | N11: =I11 -> 0.008449 | O11: =J11 -> 0.033426 | P11: =ROUND(G11/F11,2) -> 0.13 | Q11: =ROUND(H11/F11,2) -> 0.7 | R11: =ROUND(N11/L11,2) -> 0.2 | S11: =ROUND(O11/L11,2) -> 0.8
A12: 4194304 | B12: 8 | C12: 0 | D12: 64 | E12: 237.0608 | F12: 0.27391 | G12: 0.134331 | H12: 0.093899 | I12: 0.008319 | J12: 0.134242 | K12: =G12+H12+I12 -> 0.236549 | L12: =G12+I12 -> 0.14265 | M12: =H12 -> 0.093899 | N12: =I12 -> 0.008319 | O12: =J12 -> 0.134242 | P12: =ROUND(G12/F12,2) -> 0.49 | Q12: =ROUND(H12/F12,2) -> 0.34 | R12: =ROUND(N12/L12,2) -> 0.06 | S12: =ROUND(O12/L12,2) -> 0.94
A13: 4194304 | B13: 8 | C13: -1 | D13: 256 | E13: 611.5178 | F13: 0.652835 | G13: 0.532228 | H13: 0.069224 | I13: 0.009567 | J13: 0.532139 | K13: =G13+H13+I13 -> 0.611019 | L13: =G13+I13 -> 0.541795 | M13: =H13 -> 0.069224 | N13: =I13 -> 0.009567 | O13: =J13 -> 0.532139 | P13: =ROUND(G13/F13,2) -> 0.82 | Q13: =ROUND(H13/F13,2) -> 0.11 | R13: =ROUND(N13/L13,2) -> 0.02 | S13: =ROUND(O13/L13,2) -> 0.98
A14: 16777216 | B14: 9 | C14: 1 | D14: 16 | E14: 921.4235 | F14: 1.096089 | G14: 0.132339 | H14: 0.752471 | I14: 0.036029 | J14: 0.132238 | K14: =G14+H14+I14 -> 0.920839 | L14: =G14+I14 -> 0.168368 | M14: =H14 -> 0.752471 | N14: =I14 -> 0.036029 | O14: =J14 -> 0.132238 | P14: =ROUND(G14/F14,2) -> 0.12 | Q14: =ROUND(H14/F14,2) -> 0.69 | R14: =ROUND(N14/L14,2) -> 0.21 | S14: =ROUND(O14/L14,2) -> 0.79
A15: 16777216 | B15: 9 | C15: 0 | D15: 64 | E15: 930.3776 | F15: 1.078182 | G15: 0.526802 | H15: 0.370462 | I15: 0.032583 | J15: 0.526699 | K15: =G15+H15+I15 -> 0.929847 | L15: =G15+I15 -> 0.559385 | M15: =H15 -> 0.370462 | N15: =I15 -> 0.032583 | O15: =J15 -> 0.526699 | P15: =ROUND(G15/F15,2) -> 0.49 | Q15: =ROUND(H15/F15,2) -> 0.34 | R15: =ROUND(N15/L15,2) -> 0.06 | S15: =ROUND(O15/L15,2) -> 0.94
A16: 16777216 | B16: 9 | C16: -1 | D16: 256 | E16: 2449.283 | F16: 2.60184 | G16: 2.137138 | H16: 0.277354 | I16: 0.034201 | J16: 2.137043 | K16: =G16+H16+I16 -> 2.448693 | L16: =G16+I16 -> 2.171339 | M16: =H16 -> 0.277354 | N16: =I16 -> 0.034201 | O16: =J16 -> 2.137043 | P16: =ROUND(G16/F16,2) -> 0.82 | Q16: =ROUND(H16/F16,2) -> 0.11 | R16: =ROUND(N16/L16,2) -> 0.02 | S16: =ROUND(O16/L16,2) -> 0.98
A40: N | B40: L | C40: inc | D40: t | E40: avg_time | F40: MLFMA_time | G40: nearFieldTime | H40: farFieldTime | I40: transferTime | J40: computationTime | K40: MLFMA_time | L40: nearFieldTime | M40: farFieldTime | N40: transferTime | O40: computationTime | P40: share NearField | Q40: share FarField | R40: share Transfer | S40: share Computation
A41: 65536 | B41: 5 | C41: -1 | D41: 256 | E41: 13.3284 | F41: 0.014627 | G41: 0.01099 | H41: 0.001542 | I41: 0.000359 | J41: 0.01091 | K41: 0.012891 | L41: 0.011349 | M41: 0.001542 | N41: 0.000359 | O41: 0.01091 | P41: 0.75 | Q41: 0.11 | R41: =N41/L41 -> 0.031632743 | S41: =O41/L41 -> 0.96131818
A42: 262144 | B42: 6 | C42: -1 | D42: 256 | E42: 41.6408 | F42: 0.044726 | G42: 0.03569 | H42: 0.004755 | I42: 0.000752 | J42: 0.035605 | K42: 0.041197 | L42: 0.036442 | M42: 0.004755 | N42: 0.000752 | O42: 0.035605 | P42: 0.88 | Q42: 0.12 | R42: =N42/L42 -> 0.02063553 | S42: =O42/L42 -> 0.977032
A43: 1048576 | B43: 7 | C43: -1 | D43: 256 | E43: 156.8589 | F43: 0.166777 | G43: 0.136305 | H43: 0.01783 | I43: 0.002227 | J43: 0.13621 | K43: 0.156362 | L43: 0.138532 | M43: 0.01783 | N43: 0.002227 | O43: 0.13621 | P43: 0.82 | Q43: 0.11 | R43: =N43/L43 -> 0.016075708 | S43: =O43/L43 -> 0.98323853
A44: 4194304 | B44: 8 | C44: -1 | D44: 256 | E44: 611.5178 | F44: 0.652835 | G44: 0.532228 | H44: 0.069224 | I44: 0.009567 | J44: 0.532139 | K44: 0.611019 | L44: 0.541795 | M44: 0.069224 | N44: 0.009567 | O44: 0.532139 | P44: 0.82 | Q44: 0.11 | R44: =N44/L44 -> 0.01765797 | S44: =O44/L44 -> 0.98217776
A45: 16777216 | B45: 9 | C45: -1 | D45: 256 | E45: 2449.283 | F45: 2.60184 | G45: 2.137138 | H45: 0.277354 | I45: 0.034201 | J45: 2.137043 | K45: 2.448693 | L45: 2.171339 | M45: 0.277354 | N45: 0.034201 | O45: 2.137043 | P45: 0.82 | Q45: 0.11 | R45: =N45/L45 -> 0.01575111 | S45: =O45/L45 -> 0.98420514
A46: 65536 | B46: 5 | C46: 0 | D46: 64 | E46: 5.5704 | F46: 0.006638 | G46: 0.003097 | H46: 0.001862 | I46: 0.000283 | J46: 0.00304 | K46: 0.005242 | L46: 0.00338 | M46: 0.001862 | N46: 0.000283 | O46: 0.00304 | P46: 0.47 | Q46: 0.28 | R46: =N46/L46 -> 0.083727811 | S46: =O46/L46 -> 0.89940828
A47: 262144 | B47: 6 | C47: 0 | D47: 64 | E47: 16.6467 | F47: 0.019678 | G47: 0.009223 | H47: 0.006266 | I47: 0.000732 | J47: 0.00914 | K47: 0.016221 | L47: 0.009955 | M47: 0.006266 | N47: 0.000732 | O47: 0.00914 | P47: 0.47 | Q47: 0.32 | R47: =N47/L47 -> 0.073530889 | S47: =O47/L47 -> 0.91813159
A48: 1048576 | B48: 7 | C48: 0 | D48: 64 | E48: 65.2872 | F48: 0.075347 | G48: 0.03675 | H48: 0.02579 | I48: 0.002267 | J48: 0.036667 | K48: 0.064807 | L48: 0.039017 | M48: 0.02579 | N48: 0.002267 | O48: 0.036667 | P48: 0.49 | Q48: 0.34 | R48: =N48/L48 -> 0.058102878 | S48: =O48/L48 -> 0.93976984
A49: 4194304 | B49: 8 | C49: 0 | D49: 64 | E49: 237.0608 | F49: 0.27391 | G49: 0.134331 | H49: 0.093899 | I49: 0.008319 | J49: 0.134242 | K49: 0.236549 | L49: 0.14265 | M49: 0.093899 | N49: 0.008319 | O49: 0.134242 | P49: 0.49 | Q49: 0.34 | R49: =N49/L49 -> 0.05831756 | S49: =O49/L49 -> 0.94105853
A50: 16777216 | B50: 9 | C50: 0 | D50: 64 | E50: 930.3776 | F50: 1.078182 | G50: 0.526802 | H50: 0.370462 | I50: 0.032583 | J50: 0.526699 | K50: 0.929847 | L50: 0.559385 | M50: 0.370462 | N50: 0.032583 | O50: 0.526699 | P50: 0.49 | Q50: 0.34 | R50: =N50/L50 -> 0.058247897 | S50: =O50/L50 -> 0.94156797
A51: 65536 | B51: 5 | C51: 1 | D51: 16 | E51: 5.3835 | F51: 0.006635 | G51: 0.000865 | H51: 0.003789 | I51: 0.000337 | J51: 0.000787 | K51: 0.004991 | L51: 0.001202 | M51: 0.003789 | N51: 0.000337 | O51: 0.000787 | P51: 0.13 | Q51: 0.57 | R51: =N51/L51 -> 0.28036606 | S51: =O51/L51 -> 0.6547421
A52: 262144 | B52: 6 | C52: 1 | D52: 16 | E52: 14.998 | F52: 0.018151 | G52: 0.002218 | H52: 0.01164 | I52: 0.000736 | J52: 0.002143 | K52: 0.014594 | L52: 0.002954 | M52: 0.01164 | N52: 0.000736 | O52: 0.002143 | P52: 0.12 | Q52: 0.64 | R52: =N52/L52 -> 0.24915369 | S52: =O52/L52 -> 0.72545701
... A55: 16777216 | B55: 9 | C55: 1 | D55: 16 | E55: 921.4235 | F55: 1.096089 | G55: 0.132339 | H55: 0.752471 | I55: 0.036029 | J55: 0.132238 | K55: 0.920839 | L55: 0.168368 | M55: 0.752471 | N55: 0.036029 | O55: 0.132238 | P55: 0.12 | Q55: 0.69 | R55: =N55/L55 -> 0.21398959 | S55: =O55/L55 -> 0.78541053
A59: N | B59: t | C59: shareTransfer | D59: shareCompute | E59: pred share transfer | F59: pred share compute
A60: 65536 | B60: 256 | C60: =R41 -> 0.031632743 | D60: =S41 -> 0.96131818 | E60: =(3.72/B60) -> 0.01453125 | F60: =1-E60 -> 0.98546875
A61: 262144 | B61: 256 | C61: =R42 -> 0.02063553 | D61: =S42 -> 0.977032 | E61: =(3.72/B61) -> 0.01453125 | F61: =1-E61 -> 0.98546875
A62: 1048576 | B62: 256 | C62: =R43 -> 0.016075708 | D62: =S43 -> 0.98323853 | E62: =(3.72/B62) -> 0.01453125 | F62: =1-E62 -> 0.98546875
A63: 4194304 | B63: 256 | C63: =R44 -> 0.01765797 | D63: =S44 -> 0.98217776 | E63: =(3.72/B63) -> 0.01453125 | F63: =1-E63 -> 0.98546875
A64: 16777216 | B64: 256 | C64: =R45 -> 0.01575111 | D64: =S45 -> 0.98420514 | E64: =(3.72/B64) -> 0.01453125 | F64: =1-E64 -> 0.98546875
A65: 65536 | B65: 64 | C65: =R46 -> 0.083727811 | D65: =S46 -> 0.89940828 | E65: =(3.72/B65) -> 0.058125 | F65: =1-E65 -> 0.941875
A66: 262144 | B66: 64 | C66: =R47 -> 0.073530889 | D66: =S47 -> 0.91813159 | E66: =(3.72/B66) -> 0.058125 | F66: =1-E66 -> 0.941875
A67: 1048576 | B67: 64 | C67: =R48 -> 0.058102878 | D67: =S48 -> 0.93976984 | E67: =(3.72/B67) -> 0.058125 | F67: =1-E67 -> 0.941875
A68: 4194304 | B68: 64 | C68: =R49 -> 0.05831756 | D68: =S49 -> 0.94105853 | E68: =(3.72/B68) -> 0.058125 | F68: =1-E68 -> 0.941875
...

Sheet X level
A1: N | B1: Dense Tree L’=L-1 256 Box per Cluster | E1: Base Tree 64 Box per Cluster | G1: Less Dense Tree L’=L+1 16 Box per Cluster
B2: P2P SpeedUp | C2: P2P Share | D2: Overall SpeedUp | E2: P2P Share | F2: Base Level | G2: P2P SpeedUp | H2: P2P Share | I2: Overall SpeedUp
A3: 65536 | B3: =ROUND(non_redundnat!L3/non_redundnat!L4,2) -> 0.3 | C3: =non_redundnat!P4 -> 0.75 | D3: =ROUND(non_redundnat!K3/non_redundnat!K4,2) -> 0.41 | E3: =non_redundnat!P3 -> 0.47 | F3: 5 | G3: =ROUND(non_redundnat!L3/non_redundnat!L2,2) -> 2.81 | H3: =non_redundnat!P2 -> 0.13 | I3: =ROUND(non_redundnat!K3/non_redundnat!K2,2) -> 1.05
A4: 262144 | B4: =ROUND(non_redundnat!L6/non_redundnat!L7,2) -> 0.27 | C4: =non_redundnat!P7 -> 0.88 | D4: =ROUND(non_redundnat!K6/non_redundnat!K7,2) -> 0.39 | E4: =non_redundnat!P6 -> 0.47 | F4: 6 | G4: =ROUND(non_redundnat!L6/non_redundnat!L5,2) -> 3.37 | H4: =non_redundnat!P5 -> 0.12 | I4: =ROUND(non_redundnat!K6/non_redundnat!K5,2) -> 1.11
A5: 1048576 | B5: =ROUND(non_redundnat!L9/non_redundnat!L10,2) -> 0.28 | C5: =non_redundnat!P10 -> 0.82 | D5: =ROUND(non_redundnat!K9/non_redundnat!K10,2) -> 0.41 | E5: =non_redundnat!P9 -> 0.49 | F5: 7 | G5: =ROUND(non_redundnat!L9/non_redundnat!L8,2) -> 3.35 | H5: =non_redundnat!P8 -> 0.13 | I5: =ROUND(non_redundnat!K9/non_redundnat!K8,2) -> 1.02
A6: 4194304 | B6: =ROUND(non_redundnat!L12/non_redundnat!L13,2) -> 0.26 | C6: =non_redundnat!P13 -> 0.82 | D6: =ROUND(non_redundnat!K12/non_redundnat!K13,2) -> 0.39 | E6: =non_redundnat!P12 -> 0.49 | F6: 8 | G6: =ROUND(non_redundnat!L12/non_redundnat!L11,2) -> 3.4 | H6: =non_redundnat!P11 -> 0.13 | I6: =ROUND(non_redundnat!K12/non_redundnat!K11,2) -> 1.03
A7: 16777216 | B7: =ROUND(non_redundnat!L15/non_redundnat!L16,2) -> 0.26 | C7: =non_redundnat!P16 -> 0.82 | D7: =ROUND(non_redundnat!K15/non_redundnat!K16,2) -> 0.38 | E7: =non_redundnat!P15 -> 0.49 | F7: 9 | G7: =ROUND(non_redundnat!L15/non_redundnat!L14,2) -> 3.32 | H7: =non_redundnat!P14 -> 0.12 | I7: =ROUND(non_redundnat!K15/non_redundnat!K14,2) -> 1.01
A10: Speed of Redundant Implementation to Base Implementation Base Level
A11: N | B11: Dense Tree L’=L-1 256 Box per Cluster | E11: Base Tree 64 Box per Cluster | G11: Less Dense Tree L’=L+1 16 Box per Cluster
B12: P2P SpeedUp | C12: P2P Share | D12: Overall SpeedUp | E12: P2P Share | F12: Base Level | G12: P2P SpeedUp | H12: P2P Share | I12: Overall SpeedUp
A13: 65536 | B13: =ROUND(non_redundnat!L3/'RF 2'!O5,2) -> 0.07 | C13: ='RF 2'!S5 -> 0.97 | D13: =ROUND(non_redundnat!K3/'RF 2'!N5,2) -> 0.1 | E13: =non_redundnat!P13 -> 0.82 | F13: 5 | G13: =ROUND(non_redundnat!L3/'RF 2'!O3,2) -> 1.95 | H13: ='RF 2'!S3 -> 0.33 | I13: =ROUND(non_redundnat!K3/'RF 2'!N3,2) -> 1
A14: 262144 | B14: =ROUND(non_redundnat!L6/'RF 2'!O8,2) -> 0.14 | C14: ='RF 2'!S8 -> 0.93 | D14: =ROUND(non_redundnat!K6/'RF 2'!N8,2) -> 0.21 | E14: =non_redundnat!P16 -> 0.82 | F14: 6 | G14: =ROUND(non_redundnat!L6/'RF 2'!O6,2) -> 2.86 | H14: ='RF 2'!S6 -> 0.21 | I14: =ROUND(non_redundnat!K6/'RF 2'!N6,2) -> 0.97
A15: 1048576 | B15: =ROUND(non_redundnat!L9/'RF 2'!O11,2) -> 0.24 | C15: ='RF 2'!S11 -> 0.9 | D15: =ROUND(non_redundnat!K9/'RF 2'!N11,2) -> 0.36 | E15: =non_redundnat!P19 -> 0 | F15: 7 | G15: =ROUND(non_redundnat!L9/'RF 2'!O9,2) -> 3.67 | H15: ='RF 2'!S9 -> 0.18 | I15: =ROUND(non_redundnat!K9/'RF 2'!N9,2) -> 1.07
A16: 4194304 | B16: =ROUND(non_redundnat!L12/'RF 2'!O14,2) -> 0.28 | C16: ='RF 2'!S14 -> 0.88 | D16: =ROUND(non_redundnat!K12/'RF 2'!N14,2) -> 0.4 | E16: =non_redundnat!P22 -> 0 | F16: 8 | G16: =ROUND(non_redundnat!L12/'RF 2'!O12,2) -> 3.82 | H16: ='RF 2'!S12 -> 0.17 | I16: =ROUND(non_redundnat!K12/'RF 2'!N12,2) -> 1.05
A17: 16777216 | B17: =ROUND(non_redundnat!L15/'RF 2'!O17,2) -> 0.28 | C17: ='RF 2'!S17 -> 0.88 | D17: =ROUND(non_redundnat!K15/'RF 2'!N17,2) -> 0.41 | E17: =non_redundnat!P25 -> 0 | F17: 9 | G17: =ROUND(non_redundnat!L15/'RF 2'!O15,2) -> 3.91 | H17: ='RF 2'!S15 -> 0.16 | I17: =ROUND(non_redundnat!K15/'RF 2'!N15,2) -> 1.05

Sheet RF 2
A1: specs | G1: raw cvalues | N1: true values | S1: shaer | W1: X to base level erdundant tree
A2: N | B2: L | C2: inc | D2: t | E2: Box | F2: Duplicate Mem (MB) | G2: avg_time | H2: MLFMA_time | I2: nearFieldTime | J2: farFieldTime | K2: transferTime | L2: duplicationTime | M2: computationTime | N2: MLFMA | O2: nearField | P2: farField | Q2: TransferTime | R2: ComputationTime | S2: Share NF | T2: Share FF | U2: Share Transfer | V2: Share Computation | W2: MLFMA | X2: NF | Y2: FF | Z2: Transfer | AA2: Compute
A3: 65536 | B3: 5 | C3: 1 | D3: 16 | E3: 4 | F3: 0 | G3: 4.6202 | H3: 0.004177 | I3: 0.000675 | J3: 0.003349 | K3: 0.000207 | L3: 0.000854 | M3: 0.000602 | N3: =H3+L3+K3 -> 0.005238 | O3: =I3+L3+K3 -> 0.001736 | P3: =J3 -> 0.003349 | Q3: =K3+L3 -> 0.001061 | R3: =M3 -> 0.000602 | S3: =ROUND(O3/N3,2) -> 0.33 | T3: =ROUND(P3/N3,2) -> 0.64 | U3: =ROUND(Q3/O3,2) -> 0.61 | V3: =ROUND(R3/O3,2) -> 0.35 | W3: =ROUND(N$4/N3,2) -> 1.48 | X3: =ROUND(O$4/O3,2) -> 3.35 | Y3: =ROUND(P$4/P3,2) -> 0.53 | Z3: =ROUND(Q$4/Q3,2) -> 3.19 | AA3: =ROUND(R$4/R3,2) -> 3.89
A4: 65536 | B4: 5 | C4: 0 | D4: 64 | E4: 8 | F4: 1 | G4: 4.8034 | H4: 0.004347 | I4: 0.002419 | J4: 0.001771 | K4: 0.000214 | L4: 0.003174 | M4: 0.002341 | N4: =H4+L4+K4 -> 0.007735 | O4: =I4+L4+K4 -> 0.005807 | P4: =J4 -> 0.001771 | Q4: =K4+L4 -> 0.003388 | R4: =M4 -> 0.002341 | S4: =ROUND(O4/N4,2) -> 0.75 | T4: =ROUND(P4/N4,2) -> 0.23 | U4: =ROUND(Q4/O4,2) -> 0.58 | V4: =ROUND(R4/O4,2) -> 0.4 | W4: =ROUND(N$4/N4,2) -> 1 | X4: =ROUND(O$4/O4,2) -> 1 | Y4: =ROUND(P$4/P4,2) -> 1 | Z4: =ROUND(Q$4/Q4,2) -> 1 | AA4: =ROUND(R$4/R4,2) -> 1
A5: 65536 | B5: 5 | C5: -1 | D5: 256 | E5: 16 | F5: 18 | G5: 11.4169 | H5: 0.010916 | I5: 0.009203 | J5: 0.001549 | K5: 0.000214 | L5: 0.039322 | M5: 0.009119 | N5: =H5+L5+K5 -> 0.050452 | O5: =I5+L5+K5 -> 0.048739 | P5: =J5 -> 0.001549 | Q5: =K5+L5 -> 0.039536 | R5: =M5 -> 0.009119 | S5: =ROUND(O5/N5,2) -> 0.97 | T5: =ROUND(P5/N5,2) -> 0.03 | U5: =ROUND(Q5/O5,2) -> 0.81 | V5: =ROUND(R5/O5,2) -> 0.19 | W5: =ROUND(N$4/N5,2) -> 0.15 | X5: =ROUND(O$4/O5,2) -> 0.12 | Y5: =ROUND(P$4/P5,2) -> 1.14 | Z5: =ROUND(Q$4/Q5,2) -> 0.09 | AA5: =ROUND(R$4/R5,2) -> 0.26
A6: 262144 | B6: 6 | C6: 1 | D6: 16 | E6: 4 | F6: 0 | G6: 16.3371 | H6: 0.015609 | I6: 0.002305 | J6: 0.013141 | K6: 0.000472 | L6: 0.000707 | M6: 0.002232 | N6: =H6+L6+K6 -> 0.016788 | O6: =I6+L6+K6 -> 0.003484 | P6: =J6 -> 0.013141 | Q6: =K6+L6 -> 0.001179 | R6: =M6 -> 0.002232 | S6: =ROUND(O6/N6,2) -> 0.21 | T6: =ROUND(P6/N6,2) -> 0.78 | U6: =ROUND(Q6/O6,2) -> 0.34 | V6: =ROUND(R6/O6,2) -> 0.64 | W6: =ROUND(N$7/N6,2) -> 1.22 | X6: =ROUND(O$7/O6,2) -> 3.75 | Y6: =ROUND(P$7/P6,2) -> 0.56 | Z6: =ROUND(Q$7/Q6,2) -> 3.07 | AA6: =ROUND(R$7/R6,2) -> 4.19
A7: 262144 | B7: 6 | C7: 0 | D7: 64 | E7: 8 | F7: 1 | G7: 17.6534 | H7: 0.01691 | I7: 0.009437 | J7: 0.007328 | K7: 0.000484 | L7: 0.00313 | M7: 0.009362 | N7: =H7+L7+K7 -> 0.020524 | O7: =I7+L7+K7 -> 0.013051 | P7: =J7 -> 0.007328 | Q7: =K7+L7 -> 0.003614 | R7: =M7 -> 0.009362 | S7: =ROUND(O7/N7,2) -> 0.64 | T7: =ROUND(P7/N7,2) -> 0.36 | U7: =ROUND(Q7/O7,2) -> 0.28 | V7: =ROUND(R7/O7,2) -> 0.72 | W7: =ROUND(N$7/N7,2) -> 1 | X7: =ROUND(O$7/O7,2) -> 1 | Y7: =ROUND(P$7/P7,2) -> 1 | Z7: =ROUND(Q$7/Q7,2) -> 1 | AA7: =ROUND(R$7/R7,2) -> 1
A8: 262144 | B8: 6 | C8: -1 | D8: 256 | E8: 16 | F8: 18 | G8: 38.8093 | H8: 0.038009 | I8: 0.032751 | J8: 0.00509 | K8: 0.000525 | L8: 0.039219 | M8: 0.032666 | N8: =H8+L8+K8 -> 0.077753 | O8: =I8+L8+K8 -> 0.072495 | P8: =J8 -> 0.00509 | Q8: =K8+L8 -> 0.039744 | R8: =M8 -> 0.032666 | S8: =ROUND(O8/N8,2) -> 0.93 | T8: =ROUND(P8/N8,2) -> 0.07 | U8: =ROUND(Q8/O8,2) -> 0.55 | V8: =ROUND(R8/O8,2) -> 0.45 | W8: =ROUND(N$7/N8,2) -> 0.26 | X8: =ROUND(O$7/O8,2) -> 0.18 | Y8: =ROUND(P$7/P8,2) -> 1.44 | Z8: =ROUND(Q$7/Q8,2) -> 0.09 | AA8: =ROUND(R$7/R8,2) -> 0.29
A9: 1048576 | B9: 7 | C9: 1 | D9: 16 | E9: 4 | F9: 0 | G9: 59.995 | H9: 0.058182 | I9: 0.008284 | J9: 0.049732 | K9: 0.001537 | L9: 0.000819 | M9: 0.008207 | N9: =H9+L9+K9 -> 0.060538 | O9: =I9+L9+K9 -> 0.01064 | P9: =J9 -> 0.049732 | Q9: =K9+L9 -> 0.002356 | R9: =M9 -> 0.008207 | S9: =ROUND(O9/N9,2) -> 0.18 | T9: =ROUND(P9/N9,2) -> 0.82 | U9: =ROUND(Q9/O9,2) -> 0.22 | V9: =ROUND(R9/O9,2) -> 0.77 | W9: =ROUND(N$10/N9,2) -> 1.07 | X9: =ROUND(O$10/O9,2) -> 3.6 | Y9: =ROUND(P$10/P9,2) -> 0.53 | Z9: =ROUND(Q$10/Q9,2) -> 1.95 | AA9: =ROUND(R$10/R9,2) -> 4.1
A10: 1048576 | B10: 7 | C10: 0 | D10: 64 | E10: 8 | F10: 1 | G10: 61.8802 | H10: 0.06008 | I10: 0.033736 | J10: 0.026175 | K10: 0.001519 | L10: 0.003072 | M10: 0.033652 | N10: =H10+L10+K10 -> 0.064671 | O10: =I10+L10+K10 -> 0.038327 | P10: =J10 -> 0.026175 | Q10: =K10+L10 -> 0.004591 | R10: =M10 -> 0.033652 | S10: =ROUND(O10/N10,2) -> 0.59 | T10: =ROUND(P10/N10,2) -> 0.4 | U10: =ROUND(Q10/O10,2) -> 0.12 | V10: =ROUND(R10/O10,2) -> 0.88 | W10: =ROUND(N$10/N10,2) -> 1 | X10: =ROUND(O$10/O10,2) -> 1 | Y10: =ROUND(P$10/P10,2) -> 1 | Z10: =ROUND(Q$10/Q10,2) -> 1 | AA10: =ROUND(R$10/R10,2) -> 1
A11: 1048576 | B11: 7 | C11: -1 | D11: 256 | E11: 16 | F11: 18 | G11: 142.2997 | H11: 0.140492 | I11: 0.122173 | J11: 0.018134 | K11: 0.001517 | L11: 0.039283 | M11: 0.122078 | N11: =H11+L11+K11 -> 0.181292 | O11: =I11+L11+K11 -> 0.162973 | P11: =J11 -> 0.018134 | Q11: =K11+L11 -> 0.0408 | R11: =M11 -> 0.122078 | S11: =ROUND(O11/N11,2) -> 0.9 | T11: =ROUND(P11/N11,2) -> 0.1 | U11: =ROUND(Q11/O11,2) -> 0.25 | V11: =ROUND(R11/O11,2) -> 0.75 | W11: =ROUND(N$10/N11,2) -> 0.36 | X11: =ROUND(O$10/O11,2) -> 0.24 | Y11: =ROUND(P$10/P11,2) -> 1.44 | Z11: =ROUND(Q$10/Q11,2) -> 0.11 | AA11: =ROUND(R$10/R11,2) -> 0.28
A12: 4194304 | B12: 8 | C12: 1 | D12: 16 | E12: 4 | F12: 0 | G12: 224.922 | H12: 0.218867 | I12: 0.030729 | J12: 0.187943 | K12: 0.005752 | L12: 0.000854 | M12: 0.030646 | N12: =H12+L12+K12 -> 0.225473 | O12: =I12+L12+K12 -> 0.037335 | P12: =J12 -> 0.187943 | Q12: =K12+L12 -> 0.006606 | R12: =M12 -> 0.030646 | S12: =ROUND(O12/N12,2) -> 0.17 | T12: =ROUND(P12/N12,2) -> 0.83 | U12: =ROUND(Q12/O12,2) -> 0.18 | V12: =ROUND(R12/O12,2) -> 0.82 | W12: =ROUND(N$13/N12,2) -> 1.01 | X12: =ROUND(O$13/O12,2) -> 3.52 | Y12: =ROUND(P$13/P12,2) -> 0.51 | Z12: =ROUND(Q$13/Q12,2) -> 1.36 | AA12: =ROUND(R$13/R12,2) -> 4
A13: 4194304 | B13: 8 | C13: 0 | D13: 64 | E13: 8 | F13: 1 | G13: 223.8772 | H13: 0.217727 | I13: 0.122608 | J13: 0.094932 | K13: 0.005842 | L13: 0.003155 | M13: 0.122519 | N13: =H13+L13+K13 -> 0.226724 | O13: =I13+L13+K13 -> 0.131605 | P13: =J13 -> 0.094932 | Q13: =K13+L13 -> 0.008997 | R13: =M13 -> 0.122519 | S13: =ROUND(O13/N13,2) -> 0.58 | T13: =ROUND(P13/N13,2) -> 0.42 | U13: =ROUND(Q13/O13,2) -> 0.07 | V13: =ROUND(R13/O13,2) -> 0.93 | W13: =ROUND(N$13/N13,2) -> 1 | X13: =ROUND(O$13/O13,2) -> 1 | Y13: =ROUND(P$13/P13,2) -> 1 | Z13: =ROUND(Q$13/Q13,2) -> 1 | AA13: =ROUND(R$13/R13,2) -> 1
A14: 4194304 | B14: 8 | C14: -1 | D14: 256 | E14: 16 | F14: 18 | G14: 547.3787 | H14: 0.541381 | I14: 0.472706 | J14: 0.068485 | K14: 0.005679 | L14: 0.039171 | M14: 0.472608 | N14: =H14+L14+K14 -> 0.586231 | O14: =I14+L14+K14 -> 0.517556 | P14: =J14 -> 0.068485 | Q14: =K14+L14 -> 0.04485 | R14: =M14 -> 0.472608 | S14: =ROUND(O14/N14,2) -> 0.88 | T14: =ROUND(P14/N14,2) -> 0.12 | U14: =ROUND(Q14/O14,2) -> 0.09 | V14: =ROUND(R14/O14,2) -> 0.91 | W14: =ROUND(N$13/N14,2) -> 0.39 | X14: =ROUND(O$13/O14,2) -> 0.25 | Y14: =ROUND(P$13/P14,2) -> 1.39 | Z14: =ROUND(Q$13/Q14,2) -> 0.2 | AA14: =ROUND(R$13/R14,2) -> 0.26
A15: 16777216 | B15: 9 | C15: 1 | D15: 16 | E15: 4 | F15: 0 | G15: 881.3372 | H15: 0.859375 | I15: 0.120502 | J15: 0.738679 | K15: 0.021633 | L15: 0.000819 | M15: 0.120422 | N15: =H15+L15+K15 -> 0.881827 | O15: =I15+L15+K15 -> 0.142954 | P15: =J15 -> 0.738679 | Q15: =K15+L15 -> 0.022452 | R15: =M15 -> 0.120422 | S15: =ROUND(O15/N15,2) -> 0.16 | T15: =ROUND(P15/N15,2) -> 0.84 | U15: =ROUND(Q15/O15,2) -> 0.16 | V15: =ROUND(R15/O15,2) -> 0.84 | W15: =ROUND(N$16/N15,2) -> 0.99 | X15: =ROUND(O$16/O15,2) -> 3.52 | Y15: =ROUND(P$16/P15,2) -> 0.5 | Z15: =ROUND(Q$16/Q15,2) -> 1.12 | AA15: =ROUND(R$16/R15,2) -> 3.97
A16: 16777216 | B16: 9 | C16: 0 | D16: 64 | E16: 8 | F16: 1 | G16: 870.7792 | H16: 0.848421 | I16: 0.477619 | J16: 0.370588 | K16: 0.022039 | L16: 0.003133 | M16: 0.477525 | N16: =H16+L16+K16 -> 0.873593 | O16: =I16+L16+K16 -> 0.502791 | P16: =J16 -> 0.370588 | Q16: =K16+L16 -> 0.025172 | R16: =M16 -> 0.477525 | S16: =ROUND(O16/N16,2) -> 0.58 | T16: =ROUND(P16/N16,2) -> 0.42 | U16: =ROUND(Q16/O16,2) -> 0.05 | V16: =ROUND(R16/O16,2) -> 0.95 | W16: =ROUND(N$16/N16,2) -> 1 | X16: =ROUND(O$16/O16,2) -> 1 | Y16: =ROUND(P$16/P16,2) -> 1 | Z16: =ROUND(Q$16/Q16,2) -> 1 | AA16: =ROUND(R$16/R16,2) -> 1
A17: 16777216 | B17: 9 | C17: -1 | D17: 256 | E17: 16 | F17: 18 | G17: 2201.9614 | H17: 2.177972 | I17: 1.900648 | J17: 0.27712 | K17: 0.023617 | L17: 0.039296 | M17: 1.90055 | N17: =H17+L17+K17 -> 2.240885 | O17: =I17+L17+K17 -> 1.963561 | P17: =J17 -> 0.27712 | Q17: =K17+L17 -> 0.062913 | R17: =M17 -> 1.90055 | S17: =ROUND(O17/N17,2) -> 0.88 | T17: =ROUND(P17/N17,2) -> 0.12 | U17: =ROUND(Q17/O17,2) -> 0.03 | V17: =ROUND(R17/O17,2) -> 0.97 | W17: =ROUND(N$16/N17,2) -> 0.39 | X17: =ROUND(O$16/O17,2) -> 0.26 | Y17: =ROUND(P$16/P17,2) -> 1.34 | Z17: =ROUND(Q$16/Q17,2) -> 0.4 | AA17: =ROUND(R$16/R17,2) -> 0.25
H18: H = I + J
N19: N=O+P | Q19: O=Q+R

Sheet X
A1: N | B1: L | C1: inc | D1: t | E1: MLFMA_time | F1: nearFieldTime | G1: farFieldTime | H1: transferTime | I1: computationTime
A2: 65536 | B2: 5 | C2: 1 | D2: 16 | E2: =ROUND(non_redundnat!K2/'RF 2'!N3,2) -> 0.95 | F2: =ROUND(non_redundnat!L2/'RF 2'!O3,2) -> 0.69 | G2: =ROUND(non_redundnat!M2/'RF 2'!P3,2) -> 1.13 | H2: =ROUND(non_redundnat!N2/'RF 2'!Q3,2) -> 0.32 | I2: =ROUND(non_redundnat!O2/'RF 2'!R3,2) -> 1.31
A3: 65536 | B3: 5 | C3: 0 | D3: 64 | E3: =ROUND(non_redundnat!K3/'RF 2'!N4,2) -> 0.68 | F3: =ROUND(non_redundnat!L3/'RF 2'!O4,2) -> 0.58 | G3: =ROUND(non_redundnat!M3/'RF 2'!P4,2) -> 1.05 | H3: =ROUND(non_redundnat!N3/'RF 2'!Q4,2) -> 0.08 | I3: =ROUND(non_redundnat!O3/'RF 2'!R4,2) -> 1.3
A4: 65536 | B4: 5 | C4: -1 | D4: 256 | E4: =ROUND(non_redundnat!K4/'RF 2'!N5,2) -> 0.26 | F4: =ROUND(non_redundnat!L4/'RF 2'!O5,2) -> 0.23 | G4: =ROUND(non_redundnat!M4/'RF 2'!P5,2) -> 1 | H4: =ROUND(non_redundnat!N4/'RF 2'!Q5,2) -> 0.01 | I4: =ROUND(non_redundnat!O4/'RF 2'!R5,2) -> 1.2
A5: 262144 | B5: 6 | C5: 1 | D5: 16 | E5: =ROUND(non_redundnat!K5/'RF 2'!N6,2) -> 0.87 | F5: =ROUND(non_redundnat!L5/'RF 2'!O6,2) -> 0.85 | G5: =ROUND(non_redundnat!M5/'RF 2'!P6,2) -> 0.89 | H5: =ROUND(non_redundnat!N5/'RF 2'!Q6,2) -> 0.62 | I5: =ROUND(non_redundnat!O5/'RF 2'!R6,2) -> 0.96
A6: 262144 | B6: 6 | C6: 0 | D6: 64 | E6: =ROUND(non_redundnat!K6/'RF 2'!N7,2) -> 0.79 | F6: =ROUND(non_redundnat!L6/'RF 2'!O7,2) -> 0.76 | G6: =ROUND(non_redundnat!M6/'RF 2'!P7,2) -> 0.86 | H6: =ROUND(non_redundnat!N6/'RF 2'!Q7,2) -> 0.2 | I6: =ROUND(non_redundnat!O6/'RF 2'!R7,2) -> 0.98
A7: 262144 | B7: 6 | C7: -1 | D7: 256 | E7: =ROUND(non_redundnat!K7/'RF 2'!N8,2) -> 0.53 | F7: =ROUND(non_redundnat!L7/'RF 2'!O8,2) -> 0.5 | G7: =ROUND(non_redundnat!M7/'RF 2'!P8,2) -> 0.93 | H7: =ROUND(non_redundnat!N7/'RF 2'!Q8,2) -> 0.02 | I7: =ROUND(non_redundnat!O7/'RF 2'!R8,2) -> 1.09
A8: 1048576 | B8: 7 | C8: 1 | D8: 16 | E8: =ROUND(non_redundnat!K8/'RF 2'!N9,2) -> 1.05 | F8: =ROUND(non_redundnat!L8/'RF 2'!O9,2) -> 1.1 | G8: =ROUND(non_redundnat!M8/'RF 2'!P9,2) -> 1.04 | H8: =ROUND(non_redundnat!N8/'RF 2'!Q9,2) -> 0.97 | I8: =ROUND(non_redundnat!O8/'RF 2'!R9,2) -> 1.13
A9: 1048576 | B9: 7 | C9: 0 | D9: 64 | E9: =ROUND(non_redundnat!K9/'RF 2'!N10,2) -> 1 | F9: =ROUND(non_redundnat!L9/'RF 2'!O10,2) -> 1.02 | G9: =ROUND(non_redundnat!M9/'RF 2'!P10,2) -> 0.99 | H9: =ROUND(non_redundnat!N9/'RF 2'!Q10,2) -> 0.49 | I9: =ROUND(non_redundnat!O9/'RF 2'!R10,2) -> 1.09
A10: 1048576 | B10: 7 | C10: -1 | D10: 256 | E10: =ROUND(non_redundnat!K10/'RF 2'!N11,2) -> 0.86 | F10: =ROUND(non_redundnat!L10/'RF 2'!O11,2) -> 0.85 | G10: =ROUND(non_redundnat!M10/'RF 2'!P11,2) -> 0.98 | H10: =ROUND(non_redundnat!N10/'RF 2'!Q11,2) -> 0.05 | I10: =ROUND(non_redundnat!O10/'RF 2'!R11,2) -> 1.12
A11: 4194304 | B11: 8 | C11: 1 | D11: 16 | E11: =ROUND(non_redundnat!K11/'RF 2'!N12,2) -> 1.02 | F11: =ROUND(non_redundnat!L11/'RF 2'!O12,2) -> 1.12 | G11: =ROUND(non_redundnat!M11/'RF 2'!P12,2) -> 1 | H11: =ROUND(non_redundnat!N11/'RF 2'!Q12,2) -> 1.28 | I11: =ROUND(non_redundnat!O11/'RF 2'!R12,2) -> 1.09
A12: 4194304 | B12: 8 | C12: 0 | D12: 64 | E12: =ROUND(non_redundnat!K12/'RF 2'!N13,2) -> 1.04 | F12: =ROUND(non_redundnat!L12/'RF 2'!O13,2) -> 1.08 | G12: =ROUND(non_redundnat!M12/'RF 2'!P13,2) -> 0.99 | H12: =ROUND(non_redundnat!N12/'RF 2'!Q13,2) -> 0.92 | I12: =ROUND(non_redundnat!O12/'RF 2'!R13,2) -> 1.1
A13: 4194304 | B13: 8 | C13: -1 | D13: 256 | E13: =ROUND(non_redundnat!K13/'RF 2'!N14,2) -> 1.04 | F13: =ROUND(non_redundnat!L13/'RF 2'!O14,2) -> 1.05 | G13: =ROUND(non_redundnat!M13/'RF 2'!P14,2) -> 1.01 | H13: =ROUND(non_redundnat!N13/'RF 2'!Q14,2) -> 0.21 | I13: =ROUND(non_redundnat!O13/'RF 2'!R14,2) -> 1.13
... A16: 16777216 | B16: 9 | C16: -1 | D16: 256 | E16: =ROUND(non_redundnat!K16/'RF 2'!N17,2) -> 1.09 | F16: =ROUND(non_redundnat!L16/'RF 2'!O17,2) -> 1.11 | G16: =ROUND(non_redundnat!M16/'RF 2'!P17,2) -> 1 | H16: =ROUND(non_redundnat!N16/'RF 2'!Q17,2) -> 0.54 | I16: =ROUND(non_redundnat!O16/'RF 2'!R17,2) -> 1.12
S24: =X!$A$1 -> N | T24: =X!$B$1 -> L | U24: =X!$C$1 -> inc | V24: =X!$E$1 -> MLFMA_time
S25: =X!$A$2 -> 65536 | T25: =X!$B$2 -> 5 | U25: =X!$C$2 -> 1 | V25: =X!$E$2 -> 0.95
S26: =X!$A$3 -> 65536 | T26: =X!$B$3 -> 5 | U26: =X!$C$3 -> 0 | V26: =X!$E$3 -> 0.68
S27: =X!$A$4 -> 65536 | T27: =X!$B$4 -> 5 | U27: =X!$C$4 -> -1 | V27: =X!$E$4 -> 0.26
S28: =X!$A$5 -> 262144 | T28: =X!$B$5 -> 6 | U28: =X!$C$5 -> 1 | V28: =X!$E$5 -> 0.87
S29: =X!$A$6 -> 262144 | T29: =X!$B$6 -> 6 | U29: =X!$C$6 -> 0 | V29: =X!$E$6 -> 0.79
S30: =X!$A$7 -> 262144 | T30: =X!$B$7 -> 6 | U30: =X!$C$7 -> -1 | V30: =X!$E$7 -> 0.53
S31: =X!$A$8 -> 1048576 | T31: =X!$B$8 -> 7 | U31: =X!$C$8 -> 1 | V31: =X!$E$8 -> 1.05
S32: =X!$A$9 -> 1048576 | T32: =X!$B$9 -> 7 | U32: =X!$C$9 -> 0 | V32: =X!$E$9 -> 1
S33: =X!$A$10 -> 1048576 | T33: =X!$B$10 -> 7 | U33: =X!$C$10 -> -1 | V33: =X!$E$10 -> 0.86
S34: =X!$A$11 -> 4194304 | T34: =X!$B$11 -> 8 | U34: =X!$C$11 -> 1 | V34: =X!$E$11 -> 1.02
S35: =X!$A$12 -> 4194304 | T35: =X!$B$12 -> 8 | U35: =X!$C$12 -> 0 | V35: =X!$E$12 -> 1.04
S36: =X!$A$13 -> 4194304 | T36: =X!$B$13 -> 8 | U36: =X!$C$13 -> -1 | V36: =X!$E$13 -> 1.04
A37: N | B37: L | C37: inc | D37: t | E37: MLFMA_time | F37: nearFieldTime | G37: farFieldTime | H37: transferTime | I37: computationTime | S37: =X!$A$14 -> 16777216 | T37: =X!$B$14 -> 9 | U37: =X!$C$14 -> 1 | V37: =X!$E$14 -> 1.04
A38: 65536 | B38: 5 | C38: -1 | D38: 256 | E38: 0.26 | F38: 0.23 | G38: 1 | H38: 0.01 | I38: 1.2 | S38: =X!$A$15 -> 16777216 | T38: =X!$B$15 -> 9 | U38: =X!$C$15 -> 0 | V38: =X!$E$15 -> 1.06
A39: 262144 | B39: 6 | C39: -1 | D39: 256 | E39: 0.53 | F39: 0.5 | G39: 0.93 | H39: 0.02 | I39: 1.09 | S39: =X!$A$16 -> 16777216 | T39: =X!$B$16 -> 9 | U39: =X!$C$16 -> -1 | V39: =X!$E$16 -> 1.09
A40: 1048576 | B40: 7 | C40: -1 | D40: 256 | E40: 0.86 | F40: 0.85 | G40: 0.98 | H40: 0.05 | I40: 1.12
A41: 4194304 | B41: 8 | C41: -1 | D41: 256 | E41: 1.04 | F41: 1.05 | G41: 1.01 | H41: 0.21 | I41: 1.13
A42: 16777216 | B42: 9 | C42: -1 | D42: 256 | E42: 1.09 | F42: 1.11 | G42: 1 | H42: 0.54 | I42: 1.12
A43: 65536 | B43: 5 | C43: 0 | D43: 64 | E43: 0.68 | F43: 0.58 | G43: 1.05 | H43: 0.08 | I43: 1.3
A44: 262144 | B44: 6 | C44: 0 | D44: 64 | E44: 0.79 | F44: 0.76 | G44: 0.86 | H44: 0.2 | I44: 0.98
A45: 1048576 | B45: 7 | C45: 0 | D45: 64 | E45: 1 | F45: 1.02 | G45: 0.99 | H45: 0.49 | I45: 1.09
A46: 4194304 | B46: 8 | C46: 0 | D46: 64 | E46: 1.04 | F46: 1.08 | G46: 0.99 | H46: 0.92 | I46: 1.1
A47: 16777216 | B47: 9 | C47: 0 | D47: 64 | E47: 1.06 | F47: 1.11 | G47: 1 | H47: 1.29 | I47: 1.1
A48: 65536 | B48: 5 | C48: 1 | D48: 16 | E48: 0.95 | F48: 0.69 | G48: 1.13 | H48: 0.32 | I48: 1.31
A49: 262144 | B49: 6 | C49: 1 | D49: 16 | E49: 0.87 | F49: 0.85 | G49: 0.89 | H49: 0.62 | I49: 0.96
...

Sheet X transfer
A1: modeling transfer time
B3: pred transfer | C3: gussed formula | D3: pred formula 2 | E3: pred formula 3
B4: =1/(1+(4.5/X!A2)*POWER(X!D2,2)) -> 0.98272553 | C4: =1/(0.75+256*(POWER(X!D2,2)/X!A2)) -> 0.57142857 | D4: =1/(1+1/((0.22*X!A2/POWER(X!D2,2))+1+(0.25*X!A2/POWER(X!D2,3)))) -> 0.98395379 | E4: =1/(1+9*POWER(X!D2,2)/X!A2) -> 0.96603774
B5: =1/(1+(4.5/X!A3)*POWER(X!D3,2)) -> 0.7804878 | C5: =1/(0.75+256*(POWER(X!D3,2)/X!A3)) -> 0.059701493 | D5: =1/(1+1/((0.22*X!A3/POWER(X!D3,2))+1+(0.25*X!A3/POWER(X!D3,3)))) -> 0.82086879 | E5: =1/(1+9*POWER(X!D3,2)/X!A3) -> 0.64
B6: =1/(1+(4.5/X!A4)*POWER(X!D4,2)) -> 0.18181818 | C6: =1/(0.75+256*(POWER(X!D4,2)/X!A4)) -> 0.0038948393 | D6: =1/(1+1/((0.22*X!A4/POWER(X!D4,2))+1+(0.25*X!A4/POWER(X!D4,3)))) -> 0.54974761 | E6: =1/(1+9*POWER(X!D4,2)/X!A4) -> 0.1
B7: =1/(1+(4.5/X!A5)*POWER(X!D5,2)) -> 0.9956247 | C7: =1/(0.75+256*(POWER(X!D5,2)/X!A5)) -> 1 | D7: =1/(1+1/((0.22*X!A5/POWER(X!D5,2))+1+(0.25*X!A5/POWER(X!D5,3)))) -> 0.99588951 | E7: =1/(1+9*POWER(X!D5,2)/X!A5) -> 0.99128751
B8: =1/(1+(4.5/X!A6)*POWER(X!D6,2)) -> 0.93430657 | C8: =1/(0.75+256*(POWER(X!D6,2)/X!A6)) -> 0.21052632 | D8: =1/(1+1/((0.22*X!A6/POWER(X!D6,2))+1+(0.25*X!A6/POWER(X!D6,3)))) -> 0.93876301 | E8: =1/(1+9*POWER(X!D6,2)/X!A6) -> 0.87671233
B9: =1/(1+(4.5/X!A7)*POWER(X!D7,2)) -> 0.47058824 | C9: =1/(0.75+256*(POWER(X!D7,2)/X!A7)) -> 0.015444015 | D9: =1/(1+1/((0.22*X!A7/POWER(X!D7,2))+1+(0.25*X!A7/POWER(X!D7,3)))) -> 0.65324809 | E9: =1/(1+9*POWER(X!D7,2)/X!A7) -> 0.30769231
B10: =1/(1+(4.5/X!A8)*POWER(X!D8,2)) -> 0.99890257 | C10: =1/(0.75+256*(POWER(X!D8,2)/X!A8)) -> 1.2307692 | D10: =1/(1+1/((0.22*X!A8/POWER(X!D8,2))+1+(0.25*X!A8/POWER(X!D8,3)))) -> 0.998966 | E10: =1/(1+9*POWER(X!D8,2)/X!A8) -> 0.99780755
B11: =1/(1+(4.5/X!A9)*POWER(X!D9,2)) -> 0.98272553 | C11: =1/(0.75+256*(POWER(X!D9,2)/X!A9)) -> 0.57142857 | D11: =1/(1+1/((0.22*X!A9/POWER(X!D9,2))+1+(0.25*X!A9/POWER(X!D9,3)))) -> 0.98314228 | E11: =1/(1+9*POWER(X!D9,2)/X!A9) -> 0.96603774
B12: =1/(1+(4.5/X!A10)*POWER(X!D10,2)) -> 0.7804878 | C12: =1/(0.75+256*(POWER(X!D10,2)/X!A10)) -> 0.059701493 | D12: =1/(1+1/((0.22*X!A10/POWER(X!D10,2))+1+(0.25*X!A10/POWER(X!D10,3)))) -> 0.81935193 | E12: =1/(1+9*POWER(X!D10,2)/X!A10) -> 0.64
B13: =1/(1+(4.5/X!A11)*POWER(X!D11,2)) -> 0.99972542 | C13: =1/(0.75+256*(POWER(X!D11,2)/X!A11)) -> 1.3061224 | D13: =1/(1+1/((0.22*X!A11/POWER(X!D11,2))+1+(0.25*X!A11/POWER(X!D11,3)))) -> 0.9997411 | E13: =1/(1+9*POWER(X!D11,2)/X!A11) -> 0.99945099
B14: =1/(1+(4.5/X!A12)*POWER(X!D12,2)) -> 0.9956247 | C14: =1/(0.75+256*(POWER(X!D12,2)/X!A12)) -> 1 | D14: =1/(1+1/((0.22*X!A12/POWER(X!D12,2))+1+(0.25*X!A12/POWER(X!D12,3)))) -> 0.99567624 | E14: =1/(1+9*POWER(X!D12,2)/X!A12) -> 0.99128751
B15: =1/(1+(4.5/X!A13)*POWER(X!D13,2)) -> 0.93430657 | C15: =1/(0.75+256*(POWER(X!D13,2)/X!A13)) -> 0.21052632 | D15: =1/(1+1/((0.22*X!A13/POWER(X!D13,2))+1+(0.25*X!A13/POWER(X!D13,3)))) -> 0.93805173 | E15: =1/(1+9*POWER(X!D13,2)/X!A13) -> 0.87671233
B16: =1/(1+(4.5/X!A14)*POWER(X!D14,2)) -> 0.99993134 | C16: =1/(0.75+256*(POWER(X!D14,2)/X!A14)) -> 1.3264249 | D16: =1/(1+1/((0.22*X!A14/POWER(X!D14,2))+1+(0.25*X!A14/POWER(X!D14,3)))) -> 0.99993525 | E16: =1/(1+9*POWER(X!D14,2)/X!A14) -> 0.99986269
B17: =1/(1+(4.5/X!A15)*POWER(X!D15,2)) -> 0.99890257 | C17: =1/(0.75+256*(POWER(X!D15,2)/X!A15)) -> 1.2307692 | D17: =1/(1+1/((0.22*X!A15/POWER(X!D15,2))+1+(0.25*X!A15/POWER(X!D15,3)))) -> 0.998912 | E17: =1/(1+9*POWER(X!D15,2)/X!A15) -> 0.99780755 | H17: =AVERAGE(H1:H15) -> #DIV/0!
B18: =1/(1+(4.5/X!A16)*POWER(X!D16,2)) -> 0.98272553 | C18: =1/(0.75+256*(POWER(X!D16,2)/X!A16)) -> 0.57142857 | D18: =1/(1+1/((0.22*X!A16/POWER(X!D16,2))+1+(0.25*X!A16/POWER(X!D16,3)))) -> 0.98292641 | E18: =1/(1+9*POWER(X!D16,2)/X!A16) -> 0.96603774
A21: N | B21: L | C21: inc | D21: t | E21: transferTime | F21: pred formula
A22: 65536 | B22: 5 | C22: -1 | D22: 256 | E22: 0.01 | F22: =1/(1+288*POWER(D22,2)/A22) -> 0.0034602076
A23: 262144 | B23: 6 | C23: -1 | D23: 256 | E23: 0.02 | F23: =1/(1+288*POWER(D23,2)/A23) -> 0.01369863
A24: 1048576 | B24: 7 | C24: -1 | D24: 256 | E24: 0.05 | F24: =1/(1+288*POWER(D24,2)/A24) -> 0.052631579
A25: 4194304 | B25: 8 | C25: -1 | D25: 256 | E25: 0.21 | F25: =1/(1+288*POWER(D25,2)/A25) -> 0.18181818
A26: 16777216 | B26: 9 | C26: -1 | D26: 256 | E26: 0.54 | F26: =1/(1+288*POWER(D26,2)/A26) -> 0.47058824
A27: 65536 | B27: 5 | C27: 0 | D27: 64 | E27: 0.08 | F27: =1/(1+288*POWER(D27,2)/A27) -> 0.052631579
A28: 262144 | B28: 6 | C28: 0 | D28: 64 | E28: 0.2 | F28: =1/(1+288*POWER(D28,2)/A28) -> 0.18181818
A29: 1048576 | B29: 7 | C29: 0 | D29: 64 | E29: 0.49 | F29: =1/(1+288*POWER(D29,2)/A29) -> 0.47058824
A30: 4194304 | B30: 8 | C30: 0 | D30: 64 | E30: 0.92 | F30: =1/(1+288*POWER(D30,2)/A30) -> 0.7804878
A31: 16777216 | B31: 9 | C31: 0 | D31: 64 | E31: 1.29 | F31: =1/(1+288*POWER(D31,2)/A31) -> 0.93430657
A32: 65536 | B32: 5 | C32: 1 | D32: 16 | E32: 0.32 | F32: =1/(1+288*POWER(D32,2)/A32) -> 0.47058824
A33: 262144 | B33: 6 | C33: 1 | D33: 16 | E33: 0.62 | F33: =1/(1+288*POWER(D33,2)/A33) -> 0.7804878
... A36: 16777216 | B36: 9 | C36: 1 | D36: 16 | E36: 1.6 | F36: =1/(1+288*POWER(D36,2)/A36) -> 0.9956247

Sheet X computation
A1: N | B1: L | C1: inc | D1: t | E1: MLFMA_time | F1: X ComputationTime | G1: x kernel | H1: pred
A2: 65536 | B2: 5 | C2: -1 | D2: 256 | E2: 0.26 | F2: 1.2 | G2: =32/SQRT(D2) -> 2 | H2: =(32*A2+576*POWER(D2,2)+9*A2/D2)/(32*A2+288*POWER(D2,2)+9*A2/D2) -> 1.8999011
A3: 262144 | B3: 6 | C3: -1 | D3: 256 | E3: 0.53 | F3: 1.09 | G3: =32/SQRT(D3) -> 2 | H3: =(32*A3+576*POWER(D3,2)+9*A3/D3)/(32*A3+288*POWER(D3,2)+9*A3/D3) -> 1.6920737
A4: 1048576 | B4: 7 | C4: -1 | D4: 256 | E4: 0.86 | F4: 1.12 | G4: =32/SQRT(D4) -> 2 | H4: =(32*A4+576*POWER(D4,2)+9*A4/D4)/(32*A4+288*POWER(D4,2)+9*A4/D4) -> 1.3597471
A5: 4194304 | B5: 8 | C5: -1 | D5: 256 | E5: 1.04 | F5: 1.13 | G5: =32/SQRT(D5) -> 2 | H5: =(32*A5+576*POWER(D5,2)+9*A5/D5)/(32*A5+288*POWER(D5,2)+9*A5/D5) -> 1.123169
A6: 16777216 | B6: 9 | C6: -1 | D6: 256 | E6: 1.09 | F6: 1.12 | G6: =32/SQRT(D6) -> 2 | H6: =(32*A6+576*POWER(D6,2)+9*A6/D6)/(32*A6+288*POWER(D6,2)+9*A6/D6) -> 1.0339263
A7: 65536 | B7: 5 | C7: 0 | D7: 64 | E7: 0.68 | F7: 1.3 | G7: =32/SQRT(D7) -> 4 | H7: =(32*A7+576*POWER(D7,2)+9*A7/D7)/(32*A7+288*POWER(D7,2)+9*A7/D7) -> 1.3589903
A8: 262144 | B8: 6 | C8: 0 | D8: 64 | E8: 0.79 | F8: 0.98 | G8: =32/SQRT(D8) -> 4 | H8: =(32*A8+576*POWER(D8,2)+9*A8/D8)/(32*A8+288*POWER(D8,2)+9*A8/D8) -> 1.1228145
A9: 1048576 | B9: 7 | C9: 0 | D9: 64 | E9: 1 | F9: 1.09 | G9: =32/SQRT(D9) -> 4 | H9: =(32*A9+576*POWER(D9,2)+9*A9/D9)/(32*A9+288*POWER(D9,2)+9*A9/D9) -> 1.0338187
A10: 4194304 | B10: 8 | C10: 0 | D10: 64 | E10: 1.04 | F10: 1.1 | G10: =32/SQRT(D10) -> 4 | H10: =(32*A10+576*POWER(D10,2)+9*A10/D10)/(32*A10+288*POWER(D10,2)+9*A10/D10) -> 1.0086747
A11: 16777216 | B11: 9 | C11: 0 | D11: 64 | E11: 1.06 | F11: 1.1 | G11: =32/SQRT(D11) -> 4 | H11: =(32*A11+576*POWER(D11,2)+9*A11/D11)/(32*A11+288*POWER(D11,2)+9*A11/D11) -> 1.0021829
A12: 65536 | B12: 5 | C12: 1 | D12: 16 | E12: 0.95 | F12: 1.31 | G12: =32/SQRT(D12) -> 8 | H12: =(32*A12+576*POWER(D12,2)+9*A12/D12)/(32*A12+288*POWER(D12,2)+9*A12/D12) -> 1.0333952
A13: 262144 | B13: 6 | C13: 1 | D13: 16 | E13: 0.87 | F13: 0.96 | G13: =32/SQRT(D13) -> 8 | H13: =(32*A13+576*POWER(D13,2)+9*A13/D13)/(32*A13+288*POWER(D13,2)+9*A13/D13) -> 1.0085633
... A16: 16777216 | B16: 9 | C16: 1 | D16: 16 | E16: 1.04 | F16: 1.1 | G16: =32/SQRT(D16) -> 8 | H16: =(32*A16+576*POWER(D16,2)+9*A16/D16)/(32*A16+288*POWER(D16,2)+9*A16/D16) -> 1.0001349

Sheet final speedup
A1: N | B1: L | C1: inc | D1: t | E1: MLFMA_time | F1: nearFieldTime | G1: farFieldTime | H1: transferTime | I1: computationTime | J1: share Transfer | K1: share Computation | L1: pred transfer X | M1: pred computation X formula 6 | N1: pred share transfer | O1: pred share compute | P1: pred X | Q1: pred x computation | R1: pred x | T1: rel err
A2: 65536 | B2: 5 | C2: -1 | D2: 256 | E2: 0.26 | F2: 0.23 | G2: 1 | H2: 0.01 | I2: 1.2 | J2: 0.03 | K2: 0.96 | L2: =1/(1+288*POWER(D2,2)/A2) -> 0.0034602076 | M2: ='X computation'!H2 -> 1.8999011 | N2: =3.72/D2 -> 0.01453125 | O2: =1-N2 -> 0.98546875 | P2: =1/(N2/L2+O2/M2) -> 0.21194407 | Q2: ='X computation'!H2 -> 1.8999011 | R2: =1/(N2/L2+O2/Q2) -> 0.21194407 | T2: =(ABS(P2-F2)/F2)*100 -> 7.8504064
A3: 262144 | B3: 6 | C3: -1 | D3: 256 | E3: 0.53 | F3: 0.5 | G3: 0.93 | H3: 0.02 | I3: 1.09 | J3: 0.02 | K3: 0.98 | L3: =1/(1+288*POWER(D3,2)/A3) -> 0.01369863 | M3: ='X computation'!H3 -> 1.6920737 | N3: =3.72/D3 -> 0.01453125 | O3: =1-N3 -> 0.98546875 | P3: =1/(N3/L3+O3/M3) -> 0.6085745 | Q3: ='X computation'!H3 -> 1.6920737 | R3: =1/(N3/L3+O3/Q3) -> 0.6085745 | T3: =(ABS(P3-F3)/F3)*100 -> 21.714899
A4: 1048576 | B4: 7 | C4: -1 | D4: 256 | E4: 0.86 | F4: 0.85 | G4: 0.98 | H4: 0.05 | I4: 1.12 | J4: 0.02 | K4: 0.98 | L4: =1/(1+288*POWER(D4,2)/A4) -> 0.052631579 | M4: ='X computation'!H4 -> 1.3597471 | N4: =3.72/D4 -> 0.01453125 | O4: =1-N4 -> 0.98546875 | P4: =1/(N4/L4+O4/M4) -> 0.99916278 | Q4: ='X computation'!H4 -> 1.3597471 | R4: =1/(N4/L4+O4/Q4) -> 0.99916278 | T4: =(ABS(P4-F4)/F4)*100 -> 17.548562
A5: 4194304 | B5: 8 | C5: -1 | D5: 256 | E5: 1.04 | F5: 1.05 | G5: 1.01 | H5: 0.21 | I5: 1.13 | J5: 0.02 | K5: 0.98 | L5: =1/(1+288*POWER(D5,2)/A5) -> 0.18181818 | M5: ='X computation'!H5 -> 1.123169 | N5: =3.72/D5 -> 0.01453125 | O5: =1-N5 -> 0.98546875 | P5: =1/(N5/L5+O5/M5) -> 1.0445805 | Q5: ='X computation'!H5 -> 1.123169 | R5: =1/(N5/L5+O5/Q5) -> 1.0445805 | T5: =(ABS(P5-F5)/F5)*100 -> 0.51614121
A6: 16777216 | B6: 9 | C6: -1 | D6: 256 | E6: 1.09 | F6: 1.11 | G6: 1 | H6: 0.54 | I6: 1.12 | J6: 0.02 | K6: 0.98 | L6: =1/(1+288*POWER(D6,2)/A6) -> 0.47058824 | M6: ='X computation'!H6 -> 1.0339263 | N6: =3.72/D6 -> 0.01453125 | O6: =1-N6 -> 0.98546875 | P6: =1/(N6/L6+O6/M6) -> 1.0162484 | Q6: ='X computation'!H6 -> 1.0339263 | R6: =1/(N6/L6+O6/Q6) -> 1.0162484 | T6: =(ABS(P6-F6)/F6)*100 -> 8.4460945
A7: 65536 | B7: 5 | C7: 0 | D7: 64 | E7: 0.68 | F7: 0.58 | G7: 1.05 | H7: 0.08 | I7: 1.3 | J7: 0.08 | K7: 0.9 | L7: =1/(1+288*POWER(D7,2)/A7) -> 0.052631579 | M7: ='X computation'!H7 -> 1.3589903 | N7: =3.72/D7 -> 0.058125 | O7: =1-N7 -> 0.941875 | P7: =1/(N7/L7+O7/M7) -> 0.55634536 | Q7: ='X computation'!H7 -> 1.3589903 | R7: =1/(N7/L7+O7/Q7) -> 0.55634536 | T7: =(ABS(P7-F7)/F7)*100 -> 4.0783869
A8: 262144 | B8: 6 | C8: 0 | D8: 64 | E8: 0.79 | F8: 0.76 | G8: 0.86 | H8: 0.2 | I8: 0.98 | J8: 0.07 | K8: 0.92 | L8: =1/(1+288*POWER(D8,2)/A8) -> 0.18181818 | M8: ='X computation'!H8 -> 1.1228145 | N8: =3.72/D8 -> 0.058125 | O8: =1-N8 -> 0.941875 | P8: =1/(N8/L8+O8/M8) -> 0.86315585 | Q8: ='X computation'!H8 -> 1.1228145 | R8: =1/(N8/L8+O8/Q8) -> 0.86315585 | T8: =(ABS(P8-F8)/F8)*100 -> 13.573138
A9: 1048576 | B9: 7 | C9: 0 | D9: 64 | E9: 1 | F9: 1.02 | G9: 0.99 | H9: 0.49 | I9: 1.09 | J9: 0.06 | K9: 0.94 | L9: =1/(1+288*POWER(D9,2)/A9) -> 0.47058824 | M9: ='X computation'!H9 -> 1.0338187 | N9: =3.72/D9 -> 0.058125 | O9: =1-N9 -> 0.941875 | P9: =1/(N9/L9+O9/M9) -> 0.96657615 | Q9: ='X computation'!H9 -> 1.0338187 | R9: =1/(N9/L9+O9/Q9) -> 0.96657615 | T9: =(ABS(P9-F9)/F9)*100 -> 5.2376319
A10: 4194304 | B10: 8 | C10: 0 | D10: 64 | E10: 1.04 | F10: 1.08 | G10: 0.99 | H10: 0.92 | I10: 1.1 | J10: 0.06 | K10: 0.94 | L10: =1/(1+288*POWER(D10,2)/A10) -> 0.7804878 | M10: ='X computation'!H10 -> 1.0086747 | N10: =3.72/D10 -> 0.058125 | O10: =1-N10 -> 0.941875 | P10: =1/(N10/L10+O10/M10) -> 0.99182002 | Q10: ='X computation'!H10 -> 1.0086747 | R10: =1/(N10/L10+O10/Q10) -> 0.99182002 | T10: =(ABS(P10-F10)/F10)*100 -> 8.1648127
A11: 16777216 | B11: 9 | C11: 0 | D11: 64 | E11: 1.06 | F11: 1.11 | G11: 1 | H11: 1.29 | I11: 1.1 | J11: 0.06 | K11: 0.94 | L11: =1/(1+288*POWER(D11,2)/A11) -> 0.93430657 | M11: ='X computation'!H11 -> 1.0021829 | N11: =3.72/D11 -> 0.058125 | O11: =1-N11 -> 0.941875 | P11: =1/(N11/L11+O11/M11) -> 0.99796874 | Q11: ='X computation'!H11 -> 1.0021829 | R11: =1/(N11/L11+O11/Q11) -> 0.99796874 | T11: =(ABS(P11-F11)/F11)*100 -> 10.092906
A12: 65536 | B12: 5 | C12: 1 | D12: 16 | E12: 0.95 | F12: 0.69 | G12: 1.13 | H12: 0.32 | I12: 1.31 | J12: 0.28 | K12: 0.65 | L12: =1/(1+288*POWER(D12,2)/A12) -> 0.47058824 | M12: ='X computation'!H12 -> 1.0333952 | N12: =3.72/D12 -> 0.2325 | O12: =1-N12 -> 0.7675 | P12: =1/(N12/L12+O12/M12) -> 0.80856432 | Q12: ='X computation'!H12 -> 1.0333952 | R12: =1/(N12/L12+O12/Q12) -> 0.80856432 | T12: =(ABS(P12-F12)/F12)*100 -> 17.183235
A13: 262144 | B13: 6 | C13: 1 | D13: 16 | E13: 0.87 | F13: 0.85 | G13: 0.89 | H13: 0.62 | I13: 0.96 | J13: 0.25 | K13: 0.73 | L13: =1/(1+288*POWER(D13,2)/A13) -> 0.7804878 | M13: ='X computation'!H13 -> 1.0085633 | N13: =3.72/D13 -> 0.2325 | O13: =1-N13 -> 0.7675 | P13: =1/(N13/L13+O13/M13) -> 0.94439932 | Q13: ='X computation'!H13 -> 1.0085633 | R13: =1/(N13/L13+O13/Q13) -> 0.94439932 | T13: =(ABS(P13-F13)/F13)*100 -> 11.105803
... A16: 16777216 | B16: 9 | C16: 1 | D16: 16 | E16: 1.04 | F16: 1.18 | G16: 1.02 | H16: 1.6 | I16: 1.1 | J16: 0.21 | K16: 0.79 | L16: =1/(1+288*POWER(D16,2)/A16) -> 0.9956247 | M16: ='X computation'!H16 -> 1.0001349 | N16: =3.72/D16 -> 0.2325 | O16: =1-N16 -> 0.7675 | P16: =1/(N16/L16+O16/M16) -> 0.99908267 | Q16: ='X computation'!H16 -> 1.0001349 | R16: =1/(N16/L16+O16/Q16) -> 0.99908267 | T16: =(ABS(P16-F16)/F16)*100 -> 15.331978
T18: =AVERAGE(T2:T16) -> 10.819515 | U18: avg rel err
T19: =CORREL(P2:P16,F2:F16) -> 0.93050504 | U19: corr

Sheet final speedup normalized
A1: inc | B1: N | C1: L | D1: t | E1: MLFMA | F1: Near-Field | G1: FarField | H1: transfer | I1: computation | J1: share Transfer | K1: share Computation
A2: Dense Tree | B2: 65536 | C2: 5 | D2: 256 | E2: 0.26 | F2: 0.23 | G2: 1 | H2: 0.01 | I2: 1.2 | J2: 0.03 | K2: 0.96
B3: 262144 | C3: 6 | D3: 256 | E3: 0.53 | F3: 0.5 | G3: 0.93 | H3: 0.02 | I3: 1.09 | J3: 0.02 | K3: 0.98
B4: 1048576 | C4: 7 | D4: 256 | E4: 0.86 | F4: 0.85 | G4: 0.98 | H4: 0.05 | I4: 1.12 | J4: 0.02 | K4: 0.98
B5: 4194304 | C5: 8 | D5: 256 | E5: 1.04 | F5: 1.05 | G5: 1.01 | H5: 0.21 | I5: 1.13 | J5: 0.02 | K5: 0.98
B6: 16777216 | C6: 9 | D6: 256 | E6: 1.09 | F6: 1.11 | G6: 1 | H6: 0.54 | I6: 1.12 | J6: 0.02 | K6: 0.98
A7: Base Tree | B7: 65536 | C7: 5 | D7: 64 | E7: 0.68 | F7: 0.58 | G7: 1.05 | H7: 0.08 | I7: 1.3 | J7: 0.08 | K7: 0.9
B8: 262144 | C8: 6 | D8: 64 | E8: 0.79 | F8: 0.76 | G8: 0.86 | H8: 0.2 | I8: 0.98 | J8: 0.07 | K8: 0.92
B9: 1048576 | C9: 7 | D9: 64 | E9: 1 | F9: 1.02 | G9: 0.99 | H9: 0.49 | I9: 1.09 | J9: 0.06 | K9: 0.94
B10: 4194304 | C10: 8 | D10: 64 | E10: 1.04 | F10: 1.08 | G10: 0.99 | H10: 0.92 | I10: 1.1 | J10: 0.06 | K10: 0.94
B11: 16777216 | C11: 9 | D11: 64 | E11: 1.06 | F11: 1.11 | G11: 1 | H11: 1.29 | I11: 1.1 | J11: 0.06 | K11: 0.94
A12: Less Dense Tree | B12: 65536 | C12: 5 | D12: 16 | E12: 0.95 | F12: 0.69 | G12: 1.13 | H12: 0.32 | I12: 1.31 | J12: 0.28 | K12: 0.65
B13: 262144 | C13: 6 | D13: 16 | E13: 0.87 | F13: 0.85 | G13: 0.89 | H13: 0.62 | I13: 0.96 | J13: 0.25 | K13: 0.73
B14: 1048576 | C14: 7 | D14: 16 | E14: 1.05 | F14: 1.1 | G14: 1.04 | H14: 0.97 | I14: 1.13 | J14: 0.2 | K14: 0.8
B15: 4194304 | C15: 8 | D15: 16 | E15: 1.02 | F15: 1.12 | G15: 1 | H15: 1.28 | I15: 1.09 | J15: 0.2 | K15: 0.8
B16: 16777216 | C16: 9 | D16: 16 | E16: 1.04 | F16: 1.18 | G16: 1.02 | H16: 1.6 | I16: 1.1 | J16: 0.21 | K16: 0.79
A19: Normalized by farfield time
A20: inc | B20: N | C20: L | D20: t | E20: MLFMA | F20: Near-Field | G20: transfer | H20: computation | I20: Speedup redundancy to base level tree | J20: rel err | K20: avg X | L20: avg X
A21: Dense Tree | B21: 65536 | C21: 4 | D21: 256 | E21: =ROUND(E2/G2,2) -> 0.26 | F21: =ROUND(F2/G2,2) -> 0.23 | G21: =ROUND(H2/G2,2) -> 0.01 | H21: =ROUND(I2/G2,2) -> 1.2 | I21: =ROUND(E21*'X level'!D3,2) -> 0.11 | J21: =((ABS(F21-'final speedup'!P2)/F21)*100) -> 7.8504064 | K21: =AVERAGE(I21:I25) -> 0.3 | L21: =AVERAGE(I21,I26,I31) -> 0.69333333
B22: 262144 | C22: 5 | D22: 256 | E22: =ROUND(E3/G3,2) -> 0.57 | F22: =ROUND(F3/G3,2) -> 0.54 | G22: =ROUND(H3/G3,2) -> 0.02 | H22: =ROUND(I3/G3,2) -> 1.17 | I22: =ROUND(E22*'X level'!D4,2) -> 0.22 | J22: =((ABS(F22-'final speedup'!P3)/F22)*100) -> 12.698981 | L22: =AVERAGE(I22,I27,I32) -> 0.66333333
B23: 1048576 | C23: 6 | D23: 256 | E23: =ROUND(E4/G4,2) -> 0.88 | F23: =ROUND(F4/G4,2) -> 0.87 | G23: =ROUND(H4/G4,2) -> 0.05 | H23: =ROUND(I4/G4,2) -> 1.14 | I23: =ROUND(E23*'X level'!D5,2) -> 0.36 | J23: =((ABS(F23-'final speedup'!P4)/F23)*100) -> 14.846297 | L23: =AVERAGE(I23,I28,I33) -> 0.72666667 | U23: Near-Field Normalized
B24: 4194304 | C24: 7 | D24: 256 | E24: =ROUND(E5/G5,2) -> 1.03 | F24: =ROUND(F5/G5,2) -> 1.04 | G24: =ROUND(H5/G5,2) -> 0.21 | H24: =ROUND(I5/G5,2) -> 1.12 | I24: =ROUND(E24*'X level'!D6,2) -> 0.4 | J24: =((ABS(F24-'final speedup'!P5)/F24)*100) -> 0.44043435 | L24: =AVERAGE(I24,I29,I34) -> 0.81666667
B25: 16777216 | C25: 8 | D25: 256 | E25: =ROUND(E6/G6,2) -> 1.09 | F25: =ROUND(F6/G6,2) -> 1.11 | G25: =ROUND(H6/G6,2) -> 0.54 | H25: =ROUND(I6/G6,2) -> 1.12 | I25: =ROUND(E25*'X level'!D7,2) -> 0.41 | J25: =((ABS(F25-'final speedup'!P6)/F25)*100) -> 8.4460945 | L25: =AVERAGE(I25,I30,I35) -> 0.82666667
A26: Base Tree | B26: 65536 | C26: 5 | D26: 64 | E26: =ROUND(E7/G7,2) -> 0.65 | F26: =ROUND(F7/G7,2) -> 0.55 | G26: =ROUND(H7/G7,2) -> 0.08 | H26: =ROUND(I7/G7,2) -> 1.24 | I26: =E6 -> 1.09 | J26: =((ABS(F26-'final speedup'!P7)/F26)*100) -> 1.153701 | K26: =AVERAGE(I26:I30) -> 0.92
B27: 262144 | C27: 6 | D27: 64 | E27: =ROUND(E8/G8,2) -> 0.92 | F27: =ROUND(F8/G8,2) -> 0.88 | G27: =ROUND(H8/G8,2) -> 0.23 | H27: =ROUND(I8/G8,2) -> 1.14 | I27: =E7 -> 0.68 | J27: =((ABS(F27-'final speedup'!P8)/F27)*100) -> 1.9141082
B28: 1048576 | C28: 7 | D28: 64 | E28: =ROUND(E9/G9,2) -> 1.01 | F28: =ROUND(F9/G9,2) -> 1.03 | G28: =ROUND(H9/G9,2) -> 0.49 | H28: =ROUND(I9/G9,2) -> 1.1 | I28: =E8 -> 0.79 | J28: =((ABS(F28-'final speedup'!P9)/F28)*100) -> 6.1576549
B29: 4194304 | C29: 8 | D29: 64 | E29: =ROUND(E10/G10,2) -> 1.05 | F29: =ROUND(F10/G10,2) -> 1.09 | G29: =ROUND(H10/G10,2) -> 0.93 | H29: =ROUND(I10/G10,2) -> 1.11 | I29: =E9 -> 1 | J29: =((ABS(F29-'final speedup'!P10)/F29)*100) -> 9.0073374
B30: 16777216 | C30: 9 | D30: 64 | E30: =ROUND(E11/G11,2) -> 1.06 | F30: =ROUND(F11/G11,2) -> 1.11 | G30: =ROUND(H11/G11,2) -> 1.29 | H30: =ROUND(I11/G11,2) -> 1.1 | I30: =E10 -> 1.04 | J30: =((ABS(F30-'final speedup'!P11)/F30)*100) -> 10.092906
A31: Less Dense Tree | B31: 65536 | C31: 6 | D31: 16 | E31: =ROUND(E12/G12,2) -> 0.84 | F31: =ROUND(F12/G12,2) -> 0.61 | G31: =ROUND(H12/G12,2) -> 0.28 | H31: =ROUND(I12/G12,2) -> 1.16 | I31: =ROUND(E31*'X level'!I3,2) -> 0.88 | J31: =((ABS(F31-'final speedup'!P12)/F31)*100) -> 32.551528 | K31: =AVERAGE(I31:I35) -> 1.016
B32: 262144 | C32: 7 | D32: 16 | E32: =ROUND(E13/G13,2) -> 0.98 | F32: =ROUND(F13/G13,2) -> 0.96 | G32: =ROUND(H13/G13,2) -> 0.7 | H32: =ROUND(I13/G13,2) -> 1.08 | I32: =ROUND(E32*'X level'!I4,2) -> 1.09 | J32: =((ABS(F32-'final speedup'!P13)/F32)*100) -> 1.6250703
B33: 1048576 | C33: 8 | D33: 16 | E33: =ROUND(E14/G14,2) -> 1.01 | F33: =ROUND(F14/G14,2) -> 1.06 | G33: =ROUND(H14/G14,2) -> 0.93 | H33: =ROUND(I14/G14,2) -> 1.09 | I33: =ROUND(E33*'X level'!I5,2) -> 1.03 | J33: =((ABS(F33-'final speedup'!P14)/F33)*100) -> 7.0268514
B34: 4194304 | C34: 9 | D34: 16 | E34: =ROUND(E15/G15,2) -> 1.02 | F34: =ROUND(F15/G15,2) -> 1.12 | G34: =ROUND(H15/G15,2) -> 1.28 | H34: =ROUND(I15/G15,2) -> 1.09 | I34: =ROUND(E34*'X level'!I6,2) -> 1.05 | J34: =((ABS(F34-'final speedup'!P15)/F34)*100) -> 11.041036
B35: 16777216 | C35: 10 | D35: 16 | E35: =ROUND(E16/G16,2) -> 1.02 | F35: =ROUND(F16/G16,2) -> 1.16 | G35: =ROUND(H16/G16,2) -> 1.57 | H35: =ROUND(I16/G16,2) -> 1.08 | I35: =ROUND(E35*'X level'!I7,2) -> 1.03 | J35: =((ABS(F35-'final speedup'!P16)/F35)*100) -> 13.872184
K36: =AVERAGE(K21,K26,K31) -> 0.74533333
J37: =AVERAGE(J21:J35) -> 9.248306 | K37: avg rel err
J38: =CORREL(F21:F35,'final speedup'!P2:P16) -> 0.94234543 | K38: CORR
